<?xml version="1.0"?>
<!--
Modified from https://github.com/RobotLocomotion/drake/tree/master/manipulation/models/allegro_hand_description/sdf

The links and joints of the model have been renamed to be more descriptive.

NOTATION FOR NAMES OF SDF ELEMENTS
* HAND: rh, lh: denotes right hand or left hand
* FINGER: th, if, mf, rf: denotes thumb, {index, middle, ring} finger

* FINGER PHALANGES: bs, px, md, ds: denotes {base, proximal, middle, distal} phalanges.
The base phalanx is non-biological and is used to connect the non-biological axial
joint to the finger.
* THUMB PHALANGES: mp, bs, px, ds: denotes {metacarpal, base, proximal, distal}
phalanges. The metacarpal phalanx is the one in the palm of the robot. Again, the base
phalanx is non-biological.

* FINGER JOINTS: axl, mcp, pip, dip: denotes {axial, metacarpophalangeal, proximal
interphalangeal, distal interphalangeal} joints for non-thumb fingers. Axial is the
non-biological joint that allows each finger to rotate about its axis. mcp, pip, and
dip joints are in order from closest to farthest from the palm.
* THUMB JOINTS: cmc, axl, mcp, ipl: denotes {carpometacarpol, axial,
metacarpophalangeal, interphalengeal} joints for the thumb. The cmc joint is the joint
connecting the thumb to the palm, the axial joint is the non-biological joint allowing
the thumb to axially rotate, and the mcp and ip joints are in order as above.

############################
######## LINK NAMES ########
############################
| LINK |    FINGER NAME    |
|######|###################|
| palm |   algr_lh_palm    |
|######|###################|
|  0   |   algr_lh_if_bs   |
|  1   |   algr_lh_if_px   |
|  2   |   algr_lh_if_md   |
|  3   |   algr_lh_if_ds   |
|######|###################|
|  4   |   algr_lh_mf_bs   |
|  5   |   algr_lh_mf_px   |
|  6   |   algr_lh_mf_md   |
|  7   |   algr_lh_mf_ds   |
|######|###################|
|  8   |   algr_lh_rf_bs   |
|  9   |   algr_lh_rf_px   |
|  10  |   algr_lh_rf_md   |
|  11  |   algr_lh_rf_ds   |
|######|###################|
|  12  |   algr_lh_th_mp   |
|  13  |   algr_lh_th_bs   |
|  14  |   algr_lh_th_px   |
|  15  |   algr_lh_th_ds   |
#######|####################

##############################
######### JOINT NAMES ########
##############################
| JOINT |     JOINT NAME     |
|#######|####################|
|   0   |   algr_lh_if_axl   |
|   1   |   algr_lh_if_mcp   |
|   2   |   algr_lh_if_pip   |
|   3   |   algr_lh_if_dip   |
|#######|####################|
|   4   |   algr_lh_mf_axl   |
|   5   |   algr_lh_mf_mcp   |
|   6   |   algr_lh_mf_pip   |
|   7   |   algr_lh_mf_dip   |
|#######|####################|
|   8   |   algr_lh_rf_axl   |
|   9   |   algr_lh_rf_mcp   |
|   10  |   algr_lh_rf_pip   |
|   11  |   algr_lh_rf_dip   |
|#######|####################|
|   12  |   algr_lh_th_cmc   |
|   13  |   algr_lh_th_axl   |
|   14  |   algr_lh_th_mcp   |
|   15  |   algr_lh_th_ipl   |
##############################
-->
<sdf version="1.7">
  <model name="algr_lh">
    <link name="algr_lh_palm">
      <inertial>
        <mass>0.4154</mass>
        <inertia>
          <ixx>    2.089e-03</ixx>
          <ixy>-0.003635e-03</ixy>
          <ixz>   0.2233e-03</ixz>
          <iyy>    1.829e-03</iyy>
          <iyz> -0.01756e-03</iyz>
          <izz>   0.4825e-03</izz>
        </inertia>
      </inertial>
      <collision name="algr_lh_palm_collision">
        <pose>0 0 0.095 -1.5708 0 0</pose>
        <geometry>
          <mesh>
            <uri>package://frogger/models/allegro/meshes/base_link_left.obj</uri>
          </mesh>
        </geometry>
      </collision>
      <visual name="algr_lh_palm_visual">
        <pose>0 0 0.095 -1.5708 0 0</pose>
        <geometry>
          <mesh>
            <scale>1 1 1</scale>
            <uri>package://frogger/models/allegro/meshes/base_link_left.obj</uri>
          </mesh>
        </geometry>
      </visual>
    </link>
    <link name="algr_lh_if_bs">
      <pose>0 -0.0435 0.093458 0.087267 0 0</pose>
      <inertial>
        <mass>0.0119</mass>
        <inertia>
          <ixx>   1.954e-06</ixx>
          <ixy>0.003034e-06</ixy>
          <ixz> 0.08923e-06</ixz>
          <iyy>   1.179e-06</iyy>
          <iyz>-0.03707e-06</iyz>
          <izz>   1.497e-06</izz>
        </inertia>
      </inertial>
      <collision name="algr_lh_if_bs_collision">
        <geometry>
          <mesh>
            <uri>package://frogger/models/allegro/meshes/link_0.0.obj</uri>
          </mesh>
        </geometry>
      </collision>
      <visual name="algr_lh_if_bs_visual">
        <geometry>
          <mesh>
            <scale>1 1 1</scale>
            <uri>package://frogger/models/allegro/meshes/link_0.0.obj</uri>
          </mesh>
        </geometry>
      </visual>
    </link>
    <joint name="algr_lh_if_axl" type="revolute">
      <child>algr_lh_if_bs</child>
      <parent>algr_lh_palm</parent>
      <axis>
        <xyz expressed_in="__model__">0 -0.087156 0.996195</xyz>
        <limit>
          <lower>-0.47</lower>
          <upper>0.47</upper>
          <effort>0.7</effort>
        </limit>
        <dynamics>
          <damping>1.5e-2</damping>
        </dynamics>
      </axis>
    </joint>
    <link name="algr_lh_if_px">
      <pose>0 -0.044929 0.109796 0.087267 0 0</pose>
      <inertial>
        <mass>0.065</mass>
        <inertia>
          <ixx>  7.192e-05</ixx>
          <ixy>          0</ixy>
          <ixz>          0</ixz>
          <iyy>  7.438e-05</iyy>
          <iyz>0.07322e-05</iyz>
          <izz> 0.5406e-05</izz>
        </inertia>
      </inertial>
      <collision name="algr_lh_if_px_collision">
        <geometry>
          <mesh>
            <scale>1 1 1</scale>
            <uri>package://frogger/models/allegro/meshes/link_1.0.obj</uri>
          </mesh>
        </geometry>
      </collision>
      <visual name="algr_lh_if_px_visual">
        <geometry>
          <mesh>
            <scale>1 1 1</scale>
            <uri>package://frogger/models/allegro/meshes/link_1.0.obj</uri>
          </mesh>
        </geometry>
      </visual>
    </link>
    <joint name="algr_lh_if_mcp" type="revolute">
      <child>algr_lh_if_px</child>
      <parent>algr_lh_if_bs</parent>
      <axis>
        <xyz expressed_in="__model__">0 0.996195 0.087156</xyz>
        <limit>
          <lower>-0.196</lower>
          <upper>1.61</upper>
          <effort>0.7</effort>
        </limit>
        <dynamics>
          <damping>1.5e-2</damping>
        </dynamics>
      </axis>
    </joint>
    <link name="algr_lh_if_md">
      <pose>0 -0.049636 0.16359 0.087267 0 0</pose>
      <inertial>
        <mass>0.0355</mass>
        <inertia>
          <ixx>     3.169e-05</ixx>
          <ixy> 0.0001071e-05</ixy>
          <ixz>-0.0004913e-05</ixz>
          <iyy>     3.105e-05</iyy>
          <iyz>  0.003875e-05</iyz>
          <izz>    0.3203e-05</izz>
        </inertia>
      </inertial>
      <collision name="algr_lh_if_md_collision">
        <geometry>
          <mesh>
            <uri>package://frogger/models/allegro/meshes/link_2.0.obj</uri>
          </mesh>
        </geometry>
      </collision>
      <visual name="algr_lh_if_md_visual">
        <geometry>
          <mesh>
            <scale>1 1 1</scale>
            <uri>package://frogger/models/allegro/meshes/link_2.0.obj</uri>
          </mesh>
        </geometry>
      </visual>
    </link>
    <joint name="algr_lh_if_pip" type="revolute">
      <child>algr_lh_if_md</child>
      <parent>algr_lh_if_px</parent>
      <axis>
        <xyz expressed_in="__model__">0 0.996195 0.087156</xyz>
        <limit>
          <lower>-0.174</lower>
          <upper>1.709</upper>
          <effort>0.7</effort>
        </limit>
        <dynamics>
          <damping>1.5e-2</damping>
        </dynamics>
      </axis>
    </joint>
    <link name="algr_lh_if_ds">
      <pose>0 -0.052983 0.201844 0.087267 0 0</pose>
      <inertial>
        <mass>0.0264</mass>
        <inertia>
          <ixx>   1.263e-05</ixx>
          <ixy> 0.00021e-05</ixy>
          <ixz>-0.00098e-05</ixz>
          <iyy>   1.182e-05</iyy>
          <iyz> -0.0013e-05</iyz>
          <izz>  0.2484e-05</izz>
        </inertia>
      </inertial>
      <collision name="algr_lh_if_ds_collision">
        <geometry>
          <mesh>
            <uri>package://frogger/models/allegro/meshes/link_3.0.obj</uri>
          </mesh>
        </geometry>
      </collision>
      <collision name="algr_lh_if_ds_tip_collision_1">
        <pose>0 0 0.0267 0 0 0</pose>
        <geometry>
          <mesh>
            <uri>package://frogger/models/allegro/meshes/link_3.0_tip_tet.vtk</uri>
          </mesh>
        </geometry>
      </collision>
      <visual name="algr_lh_if_ds_visual">
        <geometry>
          <mesh>
            <scale>1 1 1</scale>
            <uri>package://frogger/models/allegro/meshes/link_3.0.obj</uri>
          </mesh>
        </geometry>
      </visual>
      <visual name="algr_lh_if_ds_tip_visual_1">
        <pose>0 0 0.0267 0 0 0</pose>
        <geometry>
          <mesh>
            <scale>1 1 1</scale>
            <uri>package://frogger/models/allegro/meshes/link_3.0_tip.obj</uri>
          </mesh>
        </geometry>
      </visual>
    </link>
    <joint name="algr_lh_if_dip" type="revolute">
      <child>algr_lh_if_ds</child>
      <parent>algr_lh_if_md</parent>
      <axis>
        <xyz expressed_in="__model__">0 0.996195 0.087156</xyz>
        <limit>
          <lower>-0.227</lower>
          <upper>1.618</upper>
          <effort>0.7</effort>
        </limit>
        <dynamics>
          <damping>1.5e-2</damping>
        </dynamics>
      </axis>
    </joint>
    <link name="algr_lh_mf_bs">
      <pose>0 0 0.0957 0 0 0</pose>
      <inertial>
        <mass>0.0119</mass>
        <inertia>
          <ixx>   1.954e-06</ixx>
          <ixy>0.003034e-06</ixy>
          <ixz> 0.08923e-06</ixz>
          <iyy>   1.179e-06</iyy>
          <iyz>-0.03707e-06</iyz>
          <izz>   1.497e-06</izz>
        </inertia>
      </inertial>
      <collision name="algr_lh_mf_bs_collision">
        <geometry>
          <mesh>
            <uri>package://frogger/models/allegro/meshes/link_0.0.obj</uri>
          </mesh>
        </geometry>
      </collision>
      <visual name="algr_lh_mf_bs_visual">
        <geometry>
          <mesh>
            <scale>1 1 1</scale>
            <uri>package://frogger/models/allegro/meshes/link_0.0.obj</uri>
          </mesh>
        </geometry>
      </visual>
    </link>
    <joint name="algr_lh_mf_axl" type="revolute">
      <child>algr_lh_mf_bs</child>
      <parent>algr_lh_palm</parent>
      <axis>
        <xyz expressed_in="__model__">0 0 1</xyz>
        <limit>
          <lower>-0.47</lower>
          <upper>0.47</upper>
          <effort>0.7</effort>
        </limit>
        <dynamics>
          <damping>1.5e-2</damping>
        </dynamics>
      </axis>
    </joint>
    <link name="algr_lh_mf_px">
      <pose>0 0 0.1121 0 0 0</pose>
      <inertial>
        <mass>0.065</mass>
        <inertia>
          <ixx>  7.192e-05</ixx>
          <ixy>          0</ixy>
          <ixz>          0</ixz>
          <iyy>  7.438e-05</iyy>
          <iyz>0.07322e-05</iyz>
          <izz> 0.5406e-05</izz>
        </inertia>
      </inertial>
      <collision name="algr_lh_mf_px_collision">
        <geometry>
          <mesh>
            <uri>package://frogger/models/allegro/meshes/link_1.0.obj</uri>
          </mesh>
        </geometry>
      </collision>
      <visual name="algr_lh_mf_px_visual">
        <geometry>
          <mesh>
            <scale>1 1 1</scale>
            <uri>package://frogger/models/allegro/meshes/link_1.0.obj</uri>
          </mesh>
        </geometry>
      </visual>
    </link>
    <joint name="algr_lh_mf_mcp" type="revolute">
      <child>algr_lh_mf_px</child>
      <parent>algr_lh_mf_bs</parent>
      <axis>
        <xyz expressed_in="__model__">0 1 0</xyz>
        <limit>
          <lower>-0.196</lower>
          <upper>1.61</upper>
          <effort>0.7</effort>
        </limit>
        <dynamics>
          <damping>1.5e-2</damping>
        </dynamics>
      </axis>
    </joint>
    <link name="algr_lh_mf_md">
      <pose>0 0 0.1661 0 0 0</pose>
      <inertial>
        <mass>0.0355</mass>
        <inertia>
          <ixx>     3.169e-05</ixx>
          <ixy> 0.0001071e-05</ixy>
          <ixz>-0.0004913e-05</ixz>
          <iyy>     3.105e-05</iyy>
          <iyz>  0.003875e-05</iyz>
          <izz>    0.3203e-05</izz>
        </inertia>
      </inertial>
      <collision name="algr_lh_mf_md_collision">
        <geometry>
          <mesh>
            <uri>package://frogger/models/allegro/meshes/link_2.0.obj</uri>
          </mesh>
        </geometry>
      </collision>
      <visual name="algr_lh_mf_md_visual">
        <geometry>
          <mesh>
            <scale>1 1 1</scale>
            <uri>package://frogger/models/allegro/meshes/link_2.0.obj</uri>
          </mesh>
        </geometry>
      </visual>
    </link>
    <joint name="algr_lh_mf_pip" type="revolute">
      <child>algr_lh_mf_md</child>
      <parent>algr_lh_mf_px</parent>
      <axis>
        <xyz expressed_in="__model__">0 1 0</xyz>
        <limit>
          <lower>-0.174</lower>
          <upper>1.709</upper>
          <effort>0.7</effort>
        </limit>
        <dynamics>
          <damping>1.5e-2</damping>
        </dynamics>
      </axis>
    </joint>
    <link name="algr_lh_mf_ds">
      <pose>0 0 0.2045 0 0 0</pose>
      <inertial>
        <mass>0.0264</mass>
        <inertia>
          <ixx>   1.263e-05</ixx>
          <ixy> 0.00021e-05</ixy>
          <ixz>-0.00098e-05</ixz>
          <iyy>   1.182e-05</iyy>
          <iyz> -0.0013e-05</iyz>
          <izz>  0.2484e-05</izz>
        </inertia>
      </inertial>
      <collision name="algr_lh_mf_ds_collision">
        <geometry>
          <mesh>
            <uri>package://frogger/models/allegro/meshes/link_3.0.obj</uri>
          </mesh>
        </geometry>
      </collision>
      <collision name="algr_lh_mf_ds_tip_collision_1">
        <pose>0 0 0.0267 0 0 0</pose>
        <geometry>
          <mesh>
            <uri>package://frogger/models/allegro/meshes/link_3.0_tip_tet.vtk</uri>
          </mesh>
        </geometry>
      </collision>
      <visual name="algr_lh_mf_ds_visual">
        <geometry>
          <mesh>
            <scale>1 1 1</scale>
            <uri>package://frogger/models/allegro/meshes/link_3.0.obj</uri>
          </mesh>
        </geometry>
      </visual>
      <visual name="algr_lh_mf_ds_tip_visual_1">
        <pose>0 0 0.0267 0 0 0</pose>
        <geometry>
          <mesh>
            <scale>1 1 1</scale>
            <uri>package://frogger/models/allegro/meshes/link_3.0_tip.obj</uri>
          </mesh>
        </geometry>
      </visual>
    </link>
    <joint name="algr_lh_mf_dip" type="revolute">
      <child>algr_lh_mf_ds</child>
      <parent>algr_lh_mf_md</parent>
      <axis>
        <xyz expressed_in="__model__">0 1 0</xyz>
        <limit>
          <lower>-0.227</lower>
          <upper>1.618</upper>
          <effort>0.7</effort>
        </limit>
        <dynamics>
          <damping>1.5e-2</damping>
        </dynamics>
      </axis>
    </joint>
    <link name="algr_lh_rf_bs">
      <pose>0 0.0435 0.093458 -0.087267 0 0</pose>
      <inertial>
        <mass>0.0119</mass>
        <inertia>
          <ixx>   1.954e-06</ixx>
          <ixy>0.003034e-06</ixy>
          <ixz> 0.08923e-06</ixz>
          <iyy>   1.179e-06</iyy>
          <iyz>-0.03707e-06</iyz>
          <izz>   1.497e-06</izz>
        </inertia>
      </inertial>
      <collision name="algr_lh_rf_bs_collision">
        <geometry>
          <mesh>
            <uri>package://frogger/models/allegro/meshes/link_0.0.obj</uri>
          </mesh>
        </geometry>
      </collision>
      <visual name="algr_lh_rf_bs_visual">
        <geometry>
          <mesh>
            <scale>1 1 1</scale>
            <uri>package://frogger/models/allegro/meshes/link_0.0.obj</uri>
          </mesh>
        </geometry>
      </visual>
    </link>
    <joint name="algr_lh_rf_axl" type="revolute">
      <child>algr_lh_rf_bs</child>
      <parent>algr_lh_palm</parent>
      <axis>
        <xyz expressed_in="__model__">0 0.087156 0.996195</xyz>
        <limit>
          <lower>-0.47</lower>
          <upper>0.47</upper>
          <effort>0.7</effort>
        </limit>
        <dynamics>
          <damping>1.5e-2</damping>
        </dynamics>
      </axis>
    </joint>
    <link name="algr_lh_rf_px">
      <pose>0 0.044929 0.109796 -0.087267 0 0</pose>
      <inertial>
        <mass>0.065</mass>
        <inertia>
          <ixx>  7.192e-05</ixx>
          <ixy>          0</ixy>
          <ixz>          0</ixz>
          <iyy>  7.438e-05</iyy>
          <iyz>0.07322e-05</iyz>
          <izz> 0.5406e-05</izz>
        </inertia>
      </inertial>
      <collision name="algr_lh_rf_px_collision">
        <geometry>
          <mesh>
            <uri>package://frogger/models/allegro/meshes/link_1.0.obj</uri>
          </mesh>
        </geometry>
      </collision>
      <visual name="algr_lh_rf_px_visual">
        <geometry>
          <mesh>
            <scale>1 1 1</scale>
            <uri>package://frogger/models/allegro/meshes/link_1.0.obj</uri>
          </mesh>
        </geometry>
      </visual>
    </link>
    <joint name="algr_lh_rf_mcp" type="revolute">
      <child>algr_lh_rf_px</child>
      <parent>algr_lh_rf_bs</parent>
      <axis>
        <xyz expressed_in="__model__">0 0.996195 -0.087156</xyz>
        <limit>
          <lower>-0.196</lower>
          <upper>1.61</upper>
          <effort>0.7</effort>
        </limit>
        <dynamics>
          <damping>1.5e-2</damping>
        </dynamics>
      </axis>
    </joint>
    <link name="algr_lh_rf_md">
      <pose>0 0.049636 0.16359 -0.087267 0 0</pose>
      <inertial>
        <mass>0.0355</mass>
        <inertia>
          <ixx>     3.169e-05</ixx>
          <ixy> 0.0001071e-05</ixy>
          <ixz>-0.0004913e-05</ixz>
          <iyy>     3.105e-05</iyy>
          <iyz>  0.003875e-05</iyz>
          <izz>    0.3203e-05</izz>
        </inertia>
      </inertial>
      <collision name="algr_lh_rf_md_collision">
        <geometry>
          <mesh>
            <uri>package://frogger/models/allegro/meshes/link_2.0.obj</uri>
          </mesh>
        </geometry>
      </collision>
      <visual name="algr_lh_rf_md_visual">
        <geometry>
          <mesh>
            <scale>1 1 1</scale>
            <uri>package://frogger/models/allegro/meshes/link_2.0.obj</uri>
          </mesh>
        </geometry>
      </visual>
    </link>
    <joint name="algr_lh_rf_pip" type="revolute">
      <child>algr_lh_rf_md</child>
      <parent>algr_lh_rf_px</parent>
      <axis>
        <xyz expressed_in="__model__">0 0.996195 -0.087156</xyz>
        <limit>
          <lower>-0.174</lower>
          <upper>1.709</upper>
          <effort>0.7</effort>
        </limit>
        <dynamics>
          <damping>1.5e-2</damping>
        </dynamics>
      </axis>
    </joint>
    <link name="algr_lh_rf_ds">
      <pose>0 0.052983 0.201844 -0.087267 0 0</pose>
      <inertial>
        <mass>0.0264</mass>
        <inertia>
          <ixx>   1.263e-05</ixx>
          <ixy> 0.00021e-05</ixy>
          <ixz>-0.00098e-05</ixz>
          <iyy>   1.182e-05</iyy>
          <iyz> -0.0013e-05</iyz>
          <izz>  0.2484e-05</izz>
        </inertia>
      </inertial>
      <collision name="algr_lh_rf_ds_collision">
        <geometry>
          <mesh>
            <uri>package://frogger/models/allegro/meshes/link_3.0.obj</uri>
          </mesh>
        </geometry>
      </collision>
      <collision name="algr_lh_rf_ds_tip_collision_1">
        <pose>0 0 0.0267 0 0 0</pose>
        <geometry>
          <mesh>
            <uri>package://frogger/models/allegro/meshes/link_3.0_tip_tet.vtk</uri>
          </mesh>
        </geometry>
      </collision>
      <visual name="algr_lh_rf_ds_visual">
        <geometry>
          <mesh>
            <scale>1 1 1</scale>
            <uri>package://frogger/models/allegro/meshes/link_3.0.obj</uri>
          </mesh>
        </geometry>
      </visual>
      <visual name="algr_lh_rf_ds_tip_visual_1">
        <pose>0 0 0.0267 0 0 0</pose>
        <geometry>
          <mesh>
            <scale>1 1 1</scale>
            <uri>package://frogger/models/allegro/meshes/link_3.0_tip.obj</uri>
          </mesh>
        </geometry>
      </visual>
    </link>
    <joint name="algr_lh_rf_dip" type="revolute">
      <child>algr_lh_rf_ds</child>
      <parent>algr_lh_rf_md</parent>
      <axis>
        <xyz expressed_in="__model__">0 0.996195 -0.087156</xyz>
        <limit>
          <lower>-0.227</lower>
          <upper>1.618</upper>
          <effort>0.7</effort>
        </limit>
        <dynamics>
          <damping>1.5e-2</damping>
        </dynamics>
      </axis>
    </joint>
    <link name="algr_lh_th_mp">
      <pose>-0.0182 -0.019333 0.049013 -3.14159 -1.48353 -1.5708</pose>
      <inertial>
        <mass>0.0176</mass>
        <inertia>
          <ixx> 0.8139e-05</ixx>
          <ixy> 0.2552e-05</ixy>
          <ixz> 0.3899e-05</ixz>
          <iyy>  1.314e-05</iyy>
          <iyz>-0.1463e-05</iyz>
          <izz>  1.002e-05</izz>
        </inertia>
      </inertial>
      <collision name="algr_lh_th_mp_collision">
        <pose>0 0 0 3.14159 0 0</pose>
        <geometry>
          <mesh>
            <uri>package://frogger/models/allegro/meshes/link_12.0_left.obj</uri>
          </mesh>
        </geometry>
      </collision>
      <visual name="algr_lh_th_mp_visual">
        <pose>0 0 0 3.14159 0 0</pose>
        <geometry>
          <mesh>
            <scale>1 1 1</scale>
            <uri>package://frogger/models/allegro/meshes/link_12.0_left.obj</uri>
          </mesh>
        </geometry>
      </visual>
    </link>
    <joint name="algr_lh_th_cmc" type="revolute">
      <child>algr_lh_th_mp</child>
      <parent>algr_lh_palm</parent>
      <axis>
        <xyz expressed_in="__model__">-0 -0.087156 0.996195</xyz>
        <limit>
          <lower>0.263</lower>
          <upper>1.396</upper>
          <effort>0.7</effort>
        </limit>
        <dynamics>
          <damping>1.5e-2</damping>
        </dynamics>
      </axis>
    </joint>
    <link name="algr_lh_th_bs">
      <pose>-0.0132 -0.056728 0.018638 -3.14159 -1.48353 -1.5708</pose>
      <inertial>
        <mass>0.0119</mass>
        <inertia>
          <ixx>   1.926e-06</ixx>
          <ixy> 0.00305e-06</ixy>
          <ixz> 0.08866e-06</ixz>
          <iyy>   1.153e-06</iyy>
          <iyz>-0.03645e-06</iyz>
          <izz>   1.496e-06</izz>
        </inertia>
      </inertial>
      <!-- [NOTE] this collision geometry caused problems for the Drake team -->
      <collision name='algr_lh_th_bs_collision'>
        <geometry>
          <mesh>
            <uri>package://frogger/models/allegro/meshes/link_13.0.obj</uri>
          </mesh>
        </geometry>
      </collision>
      <visual name="algr_lh_th_bs_visual">
        <geometry>
          <mesh>
            <scale>1 1 1</scale>
            <uri>package://frogger/models/allegro/meshes/link_13.0.obj</uri>
          </mesh>
        </geometry>
      </visual>
    </link>
    <joint name="algr_lh_th_axl" type="revolute">
      <child>algr_lh_th_bs</child>
      <parent>algr_lh_th_mp</parent>
      <axis>
        <xyz expressed_in="__model__">0 0.996195 0.087156</xyz>
        <limit>
          <lower>-0.105</lower>
          <upper>1.163</upper>
          <effort>0.7</effort>
        </limit>
        <dynamics>
          <damping>1.5e-2</damping>
        </dynamics>
      </axis>
    </joint>
    <link name="algr_lh_th_px">
      <pose>-0.0132 -0.074361 0.017096 -3.14159 -1.48353 -1.5708</pose>
      <inertial>
        <mass>0.038</mass>
        <inertia>
          <ixx>  3.670e-05</ixx>
          <ixy> 0.0001e-05</ixy>
          <ixz>0.01485e-05</ixz>
          <iyy>  3.540e-05</iyy>
          <iyz>-0.0037e-05</iyz>
          <izz> 0.3633e-05</izz>
        </inertia>
      </inertial>
      <collision name="algr_lh_th_px_collision">
        <geometry>
          <mesh>
            <uri>package://frogger/models/allegro/meshes/link_14.0.obj</uri>
          </mesh>
        </geometry>
      </collision>
      <visual name="algr_lh_th_px_visual">
        <geometry>
          <mesh>
            <scale>1 1 1</scale>
            <uri>package://frogger/models/allegro/meshes/link_14.0.obj</uri>
          </mesh>
        </geometry>
      </visual>
    </link>
    <joint name="algr_lh_th_mcp" type="revolute">
      <child>algr_lh_th_px</child>
      <parent>algr_lh_th_bs</parent>
      <axis>
        <xyz expressed_in="__model__">-1 0 0</xyz>
        <limit>
          <lower>-0.189</lower>
          <upper>1.644</upper>
          <effort>0.7</effort>
        </limit>
        <dynamics>
          <damping>1.5e-2</damping>
        </dynamics>
      </axis>
    </joint>
    <link name="algr_lh_th_ds">
      <pose>-0.0132 -0.125565 0.012616 -3.14159 -1.48353 -1.5708</pose>
      <inertial>
        <pose>0 0 0.012781 0 0 0</pose>
        <mass>0.0556</mass>
        <inertia>
          <ixx>  7.054e-05</ixx>
          <ixy>          0</ixy>
          <ixz>          0</ixz>
          <iyy>  6.564e-05</iyy>
          <iyz>-0.0033e-05</iyz>
          <izz>  1.954e-05</izz>
        </inertia>
      </inertial>
      <collision name="algr_lh_th_ds_collision">
        <geometry>
          <mesh>
            <scale>1 1 1</scale>
            <uri>package://frogger/models/allegro/meshes/link_15.0.obj</uri>
          </mesh>
        </geometry>
      </collision>
      <collision name="algr_lh_th_ds_tip_collision_1">
        <pose>0 0 0.0423 0 0 0</pose>
        <geometry>
          <mesh>
            <uri>package://frogger/models/allegro/meshes/link_15.0_tip_tet.vtk</uri>
          </mesh>
        </geometry>
      </collision>
      <visual name="algr_lh_th_ds_visual">
        <geometry>
          <mesh>
            <scale>1 1 1</scale>
            <uri>package://frogger/models/allegro/meshes/link_15.0.obj</uri>
          </mesh>
        </geometry>
      </visual>
      <visual name="algr_lh_th_ds_tip_visual_1">
        <pose>0 0 0.0423 0 0 0</pose>
        <geometry>
          <mesh>
            <scale>1 1 1</scale>
            <uri>package://frogger/models/allegro/meshes/link_15.0_tip.obj</uri>
          </mesh>
        </geometry>
      </visual>
    </link>
    <joint name="algr_lh_th_ipl" type="revolute">
      <child>algr_lh_th_ds</child>
      <parent>algr_lh_th_px</parent>
      <axis>
        <xyz expressed_in="__model__">-1 0 0</xyz>
        <limit>
          <lower>-0.162</lower>
          <upper>1.719</upper>
          <effort>0.7</effort>
        </limit>
        <dynamics>
          <damping>1.5e-2</damping>
        </dynamics>
      </axis>
    </joint>
    <drake:collision_filter_group name="thumb_base_cfg">
      <drake:member>algr_lh_th_bs</drake:member>
      <drake:member>algr_lh_palm</drake:member>
      <drake:ignored_collision_filter_group>
        thumb_base_cfg
      </drake:ignored_collision_filter_group>
    </drake:collision_filter_group>
  </model>
</sdf>