<?xml version="1.0"?>
<!--
Modified from https://github.com/RobotLocomotion/drake/tree/master/manipulation/models/allegro_hand_description/sdf

The links and joints of the model have been renamed to be more descriptive.

NOTATION FOR NAMES OF SDF ELEMENTS
* HAND: rh, lh: denotes right hand or left hand
* FINGER: th, if, mf, rf: denotes thumb, {index, middle, ring} finger

* FINGER PHALANGES: bs, px, md, ds: denotes {base, proximal, middle, distal} phalanges.
The base phalanx is non-biological and is used to connect the non-biological axial
joint to the finger.
* THUMB PHALANGES: mp, bs, px, ds: denotes {metacarpal, base, proximal, distal}
phalanges. The metacarpal phalanx is the one in the palm of the robot. Again, the base
phalanx is non-biological.

* FINGER JOINTS: axl, mcp, pip, dip: denotes {axial, metacarpophalangeal, proximal
interphalangeal, distal interphalangeal} joints for non-thumb fingers. Axial is the
non-biological joint that allows each finger to rotate about its axis. mcp, pip, and
dip joints are in order from closest to farthest from the palm.
* THUMB JOINTS: cmc, axl, mcp, ipl: denotes {carpometacarpol, axial,
metacarpophalangeal, interphalengeal} joints for the thumb. The cmc joint is the joint
connecting the thumb to the palm, the axial joint is the non-biological joint allowing
the thumb to axially rotate, and the mcp and ip joints are in order as above.

############################
######## LINK NAMES ########
############################
| LINK |    FINGER NAME    |
|######|###################|
| palm |   algr_lh_palm    |
|######|###################|
|  0   |   algr_lh_if_bs   |
|  1   |   algr_lh_if_px   |
|  2   |   algr_lh_if_md   |
|  3   |   algr_lh_if_ds   |
|######|###################|
|  4   |   algr_lh_mf_bs   |
|  5   |   algr_lh_mf_px   |
|  6   |   algr_lh_mf_md   |
|  7   |   algr_lh_mf_ds   |
|######|###################|
|  8   |   algr_lh_rf_bs   |
|  9   |   algr_lh_rf_px   |
|  10  |   algr_lh_rf_md   |
|  11  |   algr_lh_rf_ds   |
|######|###################|
|  12  |   algr_lh_th_mp   |
|  13  |   algr_lh_th_bs   |
|  14  |   algr_lh_th_px   |
|  15  |   algr_lh_th_ds   |
#######|####################

##############################
######### JOINT NAMES ########
##############################
| JOINT |     JOINT NAME     |
|#######|####################|
|   0   |   algr_lh_if_axl   |
|   1   |   algr_lh_if_mcp   |
|   2   |   algr_lh_if_pip   |
|   3   |   algr_lh_if_dip   |
|#######|####################|
|   4   |   algr_lh_mf_axl   |
|   5   |   algr_lh_mf_mcp   |
|   6   |   algr_lh_mf_pip   |
|   7   |   algr_lh_mf_dip   |
|#######|####################|
|   8   |   algr_lh_rf_axl   |
|   9   |   algr_lh_rf_mcp   |
|   10  |   algr_lh_rf_pip   |
|   11  |   algr_lh_rf_dip   |
|#######|####################|
|   12  |   algr_lh_th_cmc   |
|   13  |   algr_lh_th_axl   |
|   14  |   algr_lh_th_mcp   |
|   15  |   algr_lh_th_ipl   |
##############################
-->
<sdf version="1.7">
  <model name="algr_lh_simplified">
    <link name="algr_lh_palm">
      <inertial>
        <pose>-0.0093 0 0.0475 0 0 0</pose>
        <mass>0.4154</mass>
        <inertia>
          <ixx>0.00075444</ixx>
          <ixy>0</ixy>
          <ixz>0</ixz>
          <iyy>0.00037004</iyy>
          <iyz>0</iyz>
          <izz>0.00049964</izz>
        </inertia>
      </inertial>
      <collision name="algr_lh_palm_collision">
        <pose>-0.0093 0 0.0475 0 0 0</pose>
        <geometry>
          <box>
            <size>0.0408 0.113 0.095</size>
          </box>
        </geometry>
      </collision>
      <visual name="algr_lh_palm_visual">
        <pose>0 0 0.095 -1.5708 0 0</pose>
        <geometry>
          <mesh>
            <scale>1 1 1</scale>
            <uri>meshes/base_link_left.obj</uri>
          </mesh>
        </geometry>
      </visual>
    </link>
    <link name="algr_lh_if_bs">
      <pose>0 -0.0435 0.093458 0.087267 0 0</pose>
      <inertial>
        <pose>0 0 0.0082 0 0 0</pose>
        <mass>0.0119</mass>
        <inertia>
          <ixx>1.0167e-06</ixx>
          <ixy>0</ixy>
          <ixz>0</ixz>
          <iyy>6.4768e-07</iyy>
          <iyz>0</iyz>
          <izz>1.1309e-06</izz>
        </inertia>
      </inertial>
      <collision name="algr_lh_if_bs_collision">
        <pose>0 0 0.0082 0 0 0</pose>
        <geometry>
          <box>
            <size>0.0196 0.0275 0.0164</size>
          </box>
        </geometry>
      </collision>
      <visual name="algr_lh_if_bs_visual">
        <geometry>
          <mesh>
            <scale>1 1 1</scale>
            <uri>meshes/link_0.0.obj</uri>
          </mesh>
        </geometry>
      </visual>
    </link>
    <joint name="algr_lh_if_axl" type="revolute">
      <child>algr_lh_if_bs</child>
      <parent>algr_lh_palm</parent>
      <axis>
        <xyz expressed_in="__model__">0 -0.087156 0.996195</xyz>
        <limit>
          <lower>-0.47</lower>
          <upper>0.47</upper>
          <effort>0.7</effort>
        </limit>
        <dynamics>
          <damping>1.5e-2</damping>
        </dynamics>
      </axis>
    </joint>
    <link name="algr_lh_if_px">
      <pose>0 -0.044929 0.109796 0.087267 0 0</pose>
      <inertial>
        <pose>0 6.9389e-18 0.027 0 0 0</pose>
        <mass>0.065</mass>
        <inertia>
          <ixx>1.9891e-05</ixx>
          <ixy>0</ixy>
          <ixz>0</ixz>
          <iyy>1.7876e-05</iyy>
          <iyz>0</iyz>
          <izz>6.1772e-06</izz>
        </inertia>
      </inertial>
      <collision name="algr_lh_if_px_collision">
        <pose>0 0 0.027 0 0 0</pose>
        <geometry>
          <box>
            <size>0.0196 0.0275 0.054</size>
          </box>
        </geometry>
      </collision>
      <visual name="algr_lh_if_px_visual">
        <geometry>
          <mesh>
            <scale>1 1 1</scale>
            <uri>meshes/link_1.0.obj</uri>
          </mesh>
        </geometry>
      </visual>
    </link>
    <joint name="algr_lh_if_mcp" type="revolute">
      <child>algr_lh_if_px</child>
      <parent>algr_lh_if_bs</parent>
      <axis>
        <xyz expressed_in="__model__">0 0.996195 0.087156</xyz>
        <limit>
          <lower>-0.196</lower>
          <upper>1.61</upper>
          <effort>0.7</effort>
        </limit>
        <dynamics>
          <damping>1.5e-2</damping>
        </dynamics>
      </axis>
    </joint>
    <link name="algr_lh_if_md">
      <pose>0 -0.049636 0.16359 0.087267 0 0</pose>
      <inertial>
        <pose>0 -6.9389e-18 0.0192 0 0 0</pose>
        <mass>0.0355</mass>
        <inertia>
          <ixx>6.5995e-06</ixx>
          <ixy>0</ixy>
          <ixz>0</ixz>
          <iyy>5.4987e-06</iyy>
          <iyz>0</iyz>
          <izz>3.3737e-06</izz>
        </inertia>
      </inertial>
      <collision name="algr_lh_if_md_collision">
        <pose>0 0 0.0192 0 0 0</pose>
        <geometry>
          <box>
            <size>0.0196 0.0275 0.0384</size>
          </box>
        </geometry>
      </collision>
      <visual name="algr_lh_if_md_visual">
        <geometry>
          <mesh>
            <scale>1 1 1</scale>
            <uri>meshes/link_2.0.obj</uri>
          </mesh>
        </geometry>
      </visual>
    </link>
    <joint name="algr_lh_if_pip" type="revolute">
      <child>algr_lh_if_md</child>
      <parent>algr_lh_if_px</parent>
      <axis>
        <xyz expressed_in="__model__">0 0.996195 0.087156</xyz>
        <limit>
          <lower>-0.174</lower>
          <upper>1.709</upper>
          <effort>0.7</effort>
        </limit>
        <dynamics>
          <damping>1.5e-2</damping>
        </dynamics>
      </axis>
    </joint>
    <link name="algr_lh_if_ds">
      <pose>0 -0.052983 0.201844 0.087267 0 0</pose>
      <inertial>
        <pose>0 -1.3878e-17 0.011823 0 0 0</pose>
        <mass>0.0264</mass>
        <inertia>
          <ixx>4.7816e-06</ixx>
          <ixy>0</ixy>
          <ixz>0</ixz>
          <iyy>4.4476e-06</iyy>
          <iyz>0</iyz>
          <izz>2.0646e-06</izz>
        </inertia>
      </inertial>
      <collision name="algr_lh_if_ds_collision_1">
        <pose>0 0 0.00235 0 0 0</pose>
        <geometry>
          <box>
            <size>0.0196 0.0275 0.0247</size>
          </box>
        </geometry>
      </collision>
      <collision name="algr_lh_if_ds_tip_collision_1_FROGGERCOL">
        <pose>0 0 0.0267 0 0 0</pose>
        <geometry>
          <sphere>
            <radius>0.012</radius>
          </sphere>
        </geometry>
        <drake:proximity_properties>
          <drake:rigid_hydroelastic/>
          <drake:mesh_resolution_hint>0.1</drake:mesh_resolution_hint>
          <drake:hunt_crossley_dissipation>1.0</drake:hunt_crossley_dissipation>
        </drake:proximity_properties>
      </collision>
      <collision name="algr_lh_if_ds_tip_collision_2_FROGGERCOL">
        <pose>0 0 0.01335 0 0 0</pose>
        <geometry>
          <cylinder>
            <length>0.0267</length>
            <radius>0.012</radius>
          </cylinder>
        </geometry>
      </collision>
      <visual name="algr_lh_if_ds_visual">
        <geometry>
          <mesh>
            <scale>1 1 1</scale>
            <uri>meshes/link_3.0.obj</uri>
          </mesh>
        </geometry>
      </visual>
      <visual name="algr_lh_if_ds_tip_visual_1">
        <pose>0 0 0.0267 0 0 0</pose>
        <geometry>
          <mesh>
            <scale>1 1 1</scale>
            <uri>meshes/link_3.0_tip.obj</uri>
          </mesh>
        </geometry>
      </visual>
    </link>
    <joint name="algr_lh_if_dip" type="revolute">
      <child>algr_lh_if_ds</child>
      <parent>algr_lh_if_md</parent>
      <axis>
        <xyz expressed_in="__model__">0 0.996195 0.087156</xyz>
        <limit>
          <lower>-0.227</lower>
          <upper>1.618</upper>
          <effort>0.7</effort>
        </limit>
        <dynamics>
          <damping>1.5e-2</damping>
        </dynamics>
      </axis>
    </joint>
    <link name="algr_lh_mf_bs">
      <pose>0 0 0.0957 0 0 0</pose>
      <inertial>
        <pose>0 0 0.0082 0 0 0</pose>
        <mass>0.0119</mass>
        <inertia>
          <ixx>1.0167e-06</ixx>
          <ixy>0</ixy>
          <ixz>0</ixz>
          <iyy>6.4768e-07</iyy>
          <iyz>0</iyz>
          <izz>1.1309e-06</izz>
        </inertia>
      </inertial>
      <collision name="algr_lh_mf_bs_collision">
        <pose>0 0 0.0082 0 0 0</pose>
        <geometry>
          <box>
            <size>0.0196 0.0275 0.0164</size>
          </box>
        </geometry>
      </collision>
      <visual name="algr_lh_mf_bs_visual">
        <geometry>
          <mesh>
            <scale>1 1 1</scale>
            <uri>meshes/link_0.0.obj</uri>
          </mesh>
        </geometry>
      </visual>
    </link>
    <joint name="algr_lh_mf_axl" type="revolute">
      <child>algr_lh_mf_bs</child>
      <parent>algr_lh_palm</parent>
      <axis>
        <xyz expressed_in="__model__">0 0 1</xyz>
        <limit>
          <lower>-0.47</lower>
          <upper>0.47</upper>
          <effort>0.7</effort>
        </limit>
        <dynamics>
          <damping>1.5e-2</damping>
        </dynamics>
      </axis>
    </joint>
    <link name="algr_lh_mf_px">
      <pose>0 0 0.1121 0 0 0</pose>
      <inertial>
        <pose>0 0 0.027 0 0 0</pose>
        <mass>0.065</mass>
        <inertia>
          <ixx>1.9891e-05</ixx>
          <ixy>0</ixy>
          <ixz>0</ixz>
          <iyy>1.7876e-05</iyy>
          <iyz>0</iyz>
          <izz>6.1772e-06</izz>
        </inertia>
      </inertial>
      <collision name="algr_lh_mf_px_collision">
        <pose>0 0 0.027 0 0 0</pose>
        <geometry>
          <box>
            <size>0.0196 0.0275 0.054</size>
          </box>
        </geometry>
      </collision>
      <visual name="algr_lh_mf_px_visual">
        <geometry>
          <mesh>
            <scale>1 1 1</scale>
            <uri>meshes/link_1.0.obj</uri>
          </mesh>
        </geometry>
      </visual>
    </link>
    <joint name="algr_lh_mf_mcp" type="revolute">
      <child>algr_lh_mf_px</child>
      <parent>algr_lh_mf_bs</parent>
      <axis>
        <xyz expressed_in="__model__">0 1 0</xyz>
        <limit>
          <lower>-0.196</lower>
          <upper>1.61</upper>
          <effort>0.7</effort>
        </limit>
        <dynamics>
          <damping>1.5e-2</damping>
        </dynamics>
      </axis>
    </joint>
    <link name="algr_lh_mf_md">
      <pose>0 0 0.1661 0 0 0</pose>
      <inertial>
        <pose>0 0 0.0192 0 0 0</pose>
        <mass>0.0355</mass>
        <inertia>
          <ixx>6.5995e-06</ixx>
          <ixy>0</ixy>
          <ixz>0</ixz>
          <iyy>5.4987e-06</iyy>
          <iyz>0</iyz>
          <izz>3.3737e-06</izz>
        </inertia>
      </inertial>
      <collision name="algr_lh_mf_md_collision">
        <pose>0 0 0.0192 0 0 0</pose>
        <geometry>
          <box>
            <size>0.0196 0.0275 0.0384</size>
          </box>
        </geometry>
      </collision>
      <visual name="algr_lh_mf_md_visual">
        <geometry>
          <mesh>
            <scale>1 1 1</scale>
            <uri>meshes/link_2.0.obj</uri>
          </mesh>
        </geometry>
      </visual>
    </link>
    <joint name="algr_lh_mf_pip" type="revolute">
      <child>algr_lh_mf_md</child>
      <parent>algr_lh_mf_px</parent>
      <axis>
        <xyz expressed_in="__model__">0 1 0</xyz>
        <limit>
          <lower>-0.174</lower>
          <upper>1.709</upper>
          <effort>0.7</effort>
        </limit>
        <dynamics>
          <damping>1.5e-2</damping>
        </dynamics>
      </axis>
    </joint>
    <link name="algr_lh_mf_ds">
      <pose>0 0 0.2045 0 0 0</pose>
      <inertial>
        <pose>0 0 0.011823 0 0 0</pose>
        <mass>0.0264</mass>
        <inertia>
          <ixx>4.7816e-06</ixx>
          <ixy>0</ixy>
          <ixz>0</ixz>
          <iyy>4.4476e-06</iyy>
          <iyz>0</iyz>
          <izz>2.0646e-06</izz>
        </inertia>
      </inertial>
      <collision name="algr_lh_mf_ds_collision_1">
        <pose>0 0 0.00235 0 0 0</pose>
        <geometry>
          <box>
            <size>0.0196 0.0275 0.0247</size>
          </box>
        </geometry>
      </collision>
      <collision name="algr_lh_mf_ds_tip_collision_1_FROGGERCOL">
        <pose>0 0 0.0267 0 0 0</pose>
        <geometry>
          <sphere>
            <radius>0.012</radius>
          </sphere>
        </geometry>
        <drake:proximity_properties>
          <drake:rigid_hydroelastic/>
          <drake:mesh_resolution_hint>0.1</drake:mesh_resolution_hint>
          <drake:hunt_crossley_dissipation>1.0</drake:hunt_crossley_dissipation>
        </drake:proximity_properties>
      </collision>
      <collision name="algr_lh_mf_ds_tip_collision_2_FROGGERCOL">
        <pose>0 0 0.01335 0 0 0</pose>
        <geometry>
          <cylinder>
            <length>0.0267</length>
            <radius>0.012</radius>
          </cylinder>
        </geometry>
      </collision>
      <visual name="algr_lh_mf_ds_visual">
        <geometry>
          <mesh>
            <scale>1 1 1</scale>
            <uri>meshes/link_3.0.obj</uri>
          </mesh>
        </geometry>
      </visual>
      <visual name="algr_lh_mf_ds_tip_visual_1">
        <pose>0 0 0.0267 0 0 0</pose>
        <geometry>
          <mesh>
            <scale>1 1 1</scale>
            <uri>meshes/link_3.0_tip.obj</uri>
          </mesh>
        </geometry>
      </visual>
    </link>
    <joint name="algr_lh_mf_dip" type="revolute">
      <child>algr_lh_mf_ds</child>
      <parent>algr_lh_mf_md</parent>
      <axis>
        <xyz expressed_in="__model__">0 1 0</xyz>
        <limit>
          <lower>-0.227</lower>
          <upper>1.618</upper>
          <effort>0.7</effort>
        </limit>
        <dynamics>
          <damping>1.5e-2</damping>
        </dynamics>
      </axis>
    </joint>
    <link name="algr_lh_rf_bs">
      <pose>0 0.0435 0.093458 -0.087267 0 0</pose>
      <inertial>
        <pose>0 0 0.0082 0 0 0</pose>
        <mass>0.0119</mass>
        <inertia>
          <ixx>1.0167e-06</ixx>
          <ixy>0</ixy>
          <ixz>0</ixz>
          <iyy>6.4768e-07</iyy>
          <iyz>0</iyz>
          <izz>1.1309e-06</izz>
        </inertia>
      </inertial>
      <collision name="algr_lh_rf_bs_collision">
        <pose>0 0 0.0082 0 0 0</pose>
        <geometry>
          <box>
            <size>0.0196 0.0275 0.0164</size>
          </box>
        </geometry>
      </collision>
      <visual name="algr_lh_rf_bs_visual">
        <geometry>
          <mesh>
            <scale>1 1 1</scale>
            <uri>meshes/link_0.0.obj</uri>
          </mesh>
        </geometry>
      </visual>
    </link>
    <joint name="algr_lh_rf_axl" type="revolute">
      <child>algr_lh_rf_bs</child>
      <parent>algr_lh_palm</parent>
      <axis>
        <xyz expressed_in="__model__">0 0.087156 0.996195</xyz>
        <limit>
          <lower>-0.47</lower>
          <upper>0.47</upper>
          <effort>0.7</effort>
        </limit>
        <dynamics>
          <damping>1.5e-2</damping>
        </dynamics>
      </axis>
    </joint>
    <link name="algr_lh_rf_px">
      <pose>0 0.044929 0.109796 -0.087267 0 0</pose>
      <inertial>
        <pose>0 -6.9389e-18 0.027 0 0 0</pose>
        <mass>0.065</mass>
        <inertia>
          <ixx>1.9891e-05</ixx>
          <ixy>0</ixy>
          <ixz>0</ixz>
          <iyy>1.7876e-05</iyy>
          <iyz>0</iyz>
          <izz>6.1772e-06</izz>
        </inertia>
      </inertial>
      <collision name="algr_lh_rf_px_collision">
        <pose>0 0 0.027 0 0 0</pose>
        <geometry>
          <box>
            <size>0.0196 0.0275 0.054</size>
          </box>
        </geometry>
      </collision>
      <visual name="algr_lh_rf_px_visual">
        <geometry>
          <mesh>
            <scale>1 1 1</scale>
            <uri>meshes/link_1.0.obj</uri>
          </mesh>
        </geometry>
      </visual>
    </link>
    <joint name="algr_lh_rf_mcp" type="revolute">
      <child>algr_lh_rf_px</child>
      <parent>algr_lh_rf_bs</parent>
      <axis>
        <xyz expressed_in="__model__">0 0.996195 -0.087156</xyz>
        <limit>
          <lower>-0.196</lower>
          <upper>1.61</upper>
          <effort>0.7</effort>
        </limit>
        <dynamics>
          <damping>1.5e-2</damping>
        </dynamics>
      </axis>
    </joint>
    <link name="algr_lh_rf_md">
      <pose>0 0.049636 0.16359 -0.087267 0 0</pose>
      <inertial>
        <pose>0 6.9389e-18 0.0192 0 0 0</pose>
        <mass>0.0355</mass>
        <inertia>
          <ixx>6.5995e-06</ixx>
          <ixy>0</ixy>
          <ixz>0</ixz>
          <iyy>5.4987e-06</iyy>
          <iyz>0</iyz>
          <izz>3.3737e-06</izz>
        </inertia>
      </inertial>
      <collision name="algr_lh_rf_md_collision">
        <pose>0 0 0.0192 0 0 0</pose>
        <geometry>
          <box>
            <size>0.0196 0.0275 0.0384</size>
          </box>
        </geometry>
      </collision>
      <visual name="algr_lh_rf_md_visual">
        <geometry>
          <mesh>
            <scale>1 1 1</scale>
            <uri>meshes/link_2.0.obj</uri>
          </mesh>
        </geometry>
      </visual>
    </link>
    <joint name="algr_lh_rf_pip" type="revolute">
      <child>algr_lh_rf_md</child>
      <parent>algr_lh_rf_px</parent>
      <axis>
        <xyz expressed_in="__model__">0 0.996195 -0.087156</xyz>
        <limit>
          <lower>-0.174</lower>
          <upper>1.709</upper>
          <effort>0.7</effort>
        </limit>
        <dynamics>
          <damping>1.5e-2</damping>
        </dynamics>
      </axis>
    </joint>
    <link name="algr_lh_rf_ds">
      <pose>0 0.052983 0.201844 -0.087267 0 0</pose>
      <inertial>
        <pose>0 1.3878e-17 0.011823 0 0 0</pose>
        <mass>0.0264</mass>
        <inertia>
          <ixx>4.7816e-06</ixx>
          <ixy>0</ixy>
          <ixz>0</ixz>
          <iyy>4.4476e-06</iyy>
          <iyz>0</iyz>
          <izz>2.0646e-06</izz>
        </inertia>
      </inertial>
      <collision name="algr_lh_rf_ds_collision_1">
        <pose>0 0 0.00235 0 0 0</pose>
        <geometry>
          <box>
            <size>0.0196 0.0275 0.0247</size>
          </box>
        </geometry>
      </collision>
      <collision name="algr_lh_rf_ds_tip_collision_1_FROGGERCOL">
        <pose>0 0 0.0267 0 0 0</pose>
        <geometry>
          <sphere>
            <radius>0.012</radius>
          </sphere>
        </geometry>
        <drake:proximity_properties>
          <drake:rigid_hydroelastic/>
          <drake:mesh_resolution_hint>0.1</drake:mesh_resolution_hint>
          <drake:hunt_crossley_dissipation>1.0</drake:hunt_crossley_dissipation>
        </drake:proximity_properties>
      </collision>
      <collision name="algr_lh_rf_ds_tip_collision_2_FROGGERCOL">
        <pose>0 0 0.01335 0 0 0</pose>
        <geometry>
          <cylinder>
            <length>0.0267</length>
            <radius>0.012</radius>
          </cylinder>
        </geometry>
      </collision>
      <visual name="algr_lh_rf_ds_visual">
        <geometry>
          <mesh>
            <scale>1 1 1</scale>
            <uri>meshes/link_3.0.obj</uri>
          </mesh>
        </geometry>
      </visual>
      <visual name="algr_lh_rf_ds_tip_visual_1">
        <pose>0 0 0.0267 0 0 0</pose>
        <geometry>
          <mesh>
            <scale>1 1 1</scale>
            <uri>meshes/link_3.0_tip.obj</uri>
          </mesh>
        </geometry>
      </visual>
    </link>
    <joint name="algr_lh_rf_dip" type="revolute">
      <child>algr_lh_rf_ds</child>
      <parent>algr_lh_rf_md</parent>
      <axis>
        <xyz expressed_in="__model__">0 0.996195 -0.087156</xyz>
        <limit>
          <lower>-0.227</lower>
          <upper>1.618</upper>
          <effort>0.7</effort>
        </limit>
        <dynamics>
          <damping>1.5e-2</damping>
        </dynamics>
      </axis>
    </joint>
    <link name="algr_lh_th_mp">
      <pose>-0.0182 -0.019333 0.049013 -3.14159 -1.48353 -1.5708</pose>
      <inertial>
        <pose>-0.0179 0.009 0.0145 0 0 0</pose>
        <mass>0.0176</mass>
        <inertia>
          <ixx>4.7318e-06</ixx>
          <ixy>0</ixy>
          <ixz>0</ixz>
          <iyy>4.9161e-06</iyy>
          <iyz>0</iyz>
          <izz>3.5752e-06</izz>
        </inertia>
      </inertial>
      <collision name="algr_lh_th_mp_collision">
        <pose>-0.0179 0.009 0.0145 0 0 0</pose>
        <geometry>
          <box>
            <size>0.0358 0.034 0.0455</size>
          </box>
        </geometry>
      </collision>
      <visual name="algr_lh_th_mp_visual">
        <pose>0 0 0 3.14159 0 0</pose>
        <geometry>
          <mesh>
            <scale>1 1 1</scale>
            <uri>meshes/link_12.0_left.obj</uri>
          </mesh>
        </geometry>
      </visual>
    </link>
    <joint name="algr_lh_th_cmc" type="revolute">
      <child>algr_lh_th_mp</child>
      <parent>algr_lh_palm</parent>
      <axis>
        <xyz expressed_in="__model__">-0 -0.087156 0.996195</xyz>
        <limit>
          <lower>0.263</lower>
          <upper>1.396</upper>
          <effort>0.7</effort>
        </limit>
        <dynamics>
          <damping>1.5e-2</damping>
        </dynamics>
      </axis>
    </joint>
    <link name="algr_lh_th_bs">
      <pose>-0.0132 -0.056728 0.018638 -3.14159 -1.48353 -1.5708</pose>
      <inertial>
        <pose>-6.9389e-18 5.2042e-18 0.00885 0 0 0</pose>
        <mass>0.0119</mass>
        <inertia>
          <ixx>1.0606e-06</ixx>
          <ixy>0</ixy>
          <ixz>0</ixz>
          <iyy>6.9164e-07</iyy>
          <iyz>7.1621e-38</iyz>
          <izz>1.1309e-06</izz>
        </inertia>
      </inertial>
      <!-- [NOTE] this collision geometry caused problems for the Drake team -->
      <collision name='algr_lh_th_bs_collision'>
        <pose>0 0 0.00885 0 0 0</pose>
        <geometry>
          <box>
            <size>0.0196 0.0275 0.0177</size>
          </box>
        </geometry>
      </collision>
      <visual name="algr_lh_th_bs_visual">
        <geometry>
          <mesh>
            <scale>1 1 1</scale>
            <uri>meshes/link_13.0.obj</uri>
          </mesh>
        </geometry>
      </visual>
    </link>
    <joint name="algr_lh_th_axl" type="revolute">
      <child>algr_lh_th_bs</child>
      <parent>algr_lh_th_mp</parent>
      <axis>
        <xyz expressed_in="__model__">0 0.996195 0.087156</xyz>
        <limit>
          <lower>-0.105</lower>
          <upper>1.163</upper>
          <effort>0.7</effort>
        </limit>
        <dynamics>
          <damping>1.5e-2</damping>
        </dynamics>
      </axis>
    </joint>
    <link name="algr_lh_th_px">
      <pose>-0.0132 -0.074361 0.017096 -3.14159 -1.48353 -1.5708</pose>
      <inertial>
        <pose>-6.9389e-18 -3.4694e-18 0.0257 0 0 0</pose>
        <mass>0.038</mass>
        <inertia>
          <ixx>1.0761e-05</ixx>
          <ixy>0</ixy>
          <ixz>0</ixz>
          <iyy>9.5827e-06</iyy>
          <iyz>0</iyz>
          <izz>3.6113e-06</izz>
        </inertia>
      </inertial>
      <collision name="algr_lh_th_px_collision">
        <pose>0 0 0.0257 0 0 0</pose>
        <geometry>
          <box>
            <size>0.0196 0.0275 0.0514</size>
          </box>
        </geometry>
      </collision>
      <visual name="algr_lh_th_px_visual">
        <geometry>
          <mesh>
            <scale>1 1 1</scale>
            <uri>meshes/link_14.0.obj</uri>
          </mesh>
        </geometry>
      </visual>
    </link>
    <joint name="algr_lh_th_mcp" type="revolute">
      <child>algr_lh_th_px</child>
      <parent>algr_lh_th_bs</parent>
      <axis>
        <xyz expressed_in="__model__">-1 0 0</xyz>
        <limit>
          <lower>-0.189</lower>
          <upper>1.644</upper>
          <effort>0.7</effort>
        </limit>
        <dynamics>
          <damping>1.5e-2</damping>
        </dynamics>
      </axis>
    </joint>
    <link name="algr_lh_th_ds">
      <pose>-0.0132 -0.125565 0.012616 -3.14159 -1.48353 -1.5708</pose>
      <inertial>
        <pose>-6.9389e-18 1.7347e-17 0.019365 0 0 0</pose>
        <mass>0.0556</mass>
        <inertia>
          <ixx>1.6162e-05</ixx>
          <ixy>0</ixy>
          <ixz>0</ixz>
          <iyy>1.5383e-05</iyy>
          <iyz>0</iyz>
          <izz>4.4611e-06</izz>
        </inertia>
      </inertial>
      <collision name="algr_lh_th_ds_collision_1">
        <pose>0 0 0.01015 0 0 0</pose>
        <geometry>
          <box>
            <size>0.0196 0.0275 0.0403</size>
          </box>
        </geometry>
      </collision>
      <collision name="algr_lh_th_ds_tip_collision_1_FROGGERCOL">
        <pose>0 0 0.0423 0 0 0</pose>
        <geometry>
          <sphere>
            <radius>0.012</radius>
          </sphere>
        </geometry>
        <drake:proximity_properties>
          <drake:rigid_hydroelastic/>
          <drake:mesh_resolution_hint>0.1</drake:mesh_resolution_hint>
          <drake:hunt_crossley_dissipation>1.0</drake:hunt_crossley_dissipation>
        </drake:proximity_properties>
      </collision>
      <collision name="algr_lh_th_ds_tip_collision_2_FROGGERCOL">
        <pose>0 0 0.02115 0 0 0</pose>
        <geometry>
          <cylinder>
            <length>0.0423</length>
            <radius>0.012</radius>
          </cylinder>
        </geometry>
      </collision>
      <visual name="algr_lh_th_ds_visual">
        <geometry>
          <mesh>
            <scale>1 1 1</scale>
            <uri>meshes/link_15.0.obj</uri>
          </mesh>
        </geometry>
      </visual>
      <visual name="algr_lh_th_ds_tip_visual_1">
        <pose>0 0 0.0423 0 0 0</pose>
        <geometry>
          <mesh>
            <scale>1 1 1</scale>
            <uri>meshes/link_15.0_tip.obj</uri>
          </mesh>
        </geometry>
      </visual>
    </link>
    <joint name="algr_lh_th_ipl" type="revolute">
      <child>algr_lh_th_ds</child>
      <parent>algr_lh_th_px</parent>
      <axis>
        <xyz expressed_in="__model__">-1 0 0</xyz>
        <limit>
          <lower>-0.162</lower>
          <upper>1.719</upper>
          <effort>0.7</effort>
        </limit>
        <dynamics>
          <damping>1.5e-2</damping>
        </dynamics>
      </axis>
    </joint>
    <drake:collision_filter_group name="thumb_base_cfg">
      <drake:member>algr_lh_th_bs</drake:member>
      <drake:member>algr_lh_palm</drake:member>
      <drake:ignored_collision_filter_group>
        thumb_base_cfg
      </drake:ignored_collision_filter_group>
    </drake:collision_filter_group>

    <!-- adding frame for heuristic IK sampling -->
    <joint name="dummy_sampling_joint" type="fixed">
      <child>algr_lh_palm_FROGGERSAMPLE</child>
      <parent>algr_lh_palm</parent>
      <pose>0.0 0.0 0.0 0.0 0.0 0.0</pose>
    </joint>
    <link name="algr_lh_palm_FROGGERSAMPLE">
      <pose>0.0 0.0 0.095 0.0 0.0 0.0</pose>
    </link>
  </model>
</sdf>
