<?xml version="1.0"?>
<!--
FR3 arm and hand together. See individual SDF files for comments.

Transformation between arm and hand taken from here: https://github.com/frankaemika/franka_ros/blob/develop/franka_description/robots/common/franka_hand.xacro
In particular, the location of the weld from the last link to the hand is given by the
"tcp" frame, and then there's an additional rotation of the hand by -pi/4 radians about
the local z axis.

[NOTE] Joint limits are NOT enforced when the plant runs in continuous time!
-->
<sdf version="1.7">
  <model name="fr3">
    <link name="fr3_link0">
      <inertial>
        <pose>-0.02919 -0.00087947 0.056603 0 0 0</pose>
        <mass>0.62977</mass>
        <inertia>
          <ixx>0.0019025</ixx>
          <ixy>-1.2262e-05</ixy>
          <ixz>-0.00028962</ixz>
          <iyy>0.0024572</iyy>
          <iyz>-2.5958e-07</iyz>
          <izz>0.0025371</izz>
        </inertia>
      </inertial>
      <visual name="fr3_link0_visual">
        <geometry>
          <mesh>
            <scale>1 1 1</scale>
            <uri>visual/link0.obj</uri>
          </mesh>
        </geometry>
      </visual>
      <collision name="fr3_link0_collision">
        <geometry>
          <mesh>
            <uri>collision/link0.obj</uri>
          </mesh>
        </geometry>
      </collision>
    </link>

    <joint name="fr3_joint1" type="revolute">
      <child>fr3_link1</child>
      <parent>fr3_link0</parent>
      <pose relative_to="fr3_link0">0 0 0.333 0 0 0</pose>
      <axis>
        <xyz>0 0 1</xyz>
        <limit>
          <lower>-2.3093</lower>
          <upper>2.3093 </upper>
          <effort>87.0</effort>
          <velocity>2.0</velocity>
        </limit>
        <dynamics>
          <damping>0.0628</damping>  <!-- # from [1] -->
          <friction>0.2549</friction>
          <!-- <damping>21.75</damping>  # from [2]
          <friction>3.48</friction> -->
          <spring_reference>0</spring_reference>
          <spring_stiffness>0</spring_stiffness>
        </dynamics>
      </axis>
    </joint>

    <link name="fr3_link1">
      <pose relative_to="fr3_joint1">0 0 0 0 0 0</pose>
      <inertial>
        <pose>1.1399e-05 -0.031266 -0.069373 0 0 0</pose>
        <mass>4.9707</mass>
        <inertia>
          <ixx>0.02944</ixx>
          <ixy>7.0888e-07</ixy>
          <ixz>1.9159e-06</ixz>
          <iyy>0.025499</iyy>
          <iyz>0.0057465</iyz>
          <izz>0.011896</izz>
        </inertia>
      </inertial>
      <visual name="fr3_link1_visual">
        <geometry>
          <mesh>
            <scale>1 1 1</scale>
            <uri>visual/link1.obj</uri>
          </mesh>
        </geometry>
      </visual>
      <collision name="fr3_link1_collision">
        <geometry>
          <mesh>
            <uri>collision/link1.obj</uri>
          </mesh>
        </geometry>
      </collision>
    </link>
    
    <joint name="fr3_joint2" type="revolute">
      <child>fr3_link2</child>
      <parent>fr3_link1</parent>
      <pose relative_to="fr3_link1">0 0 0 -1.57079632679 0 0</pose>
      <axis>
        <xyz>0 0 1</xyz>
        <limit>
          <lower>-1.5133</lower>
          <upper>1.5133</upper>
          <effort>87.0</effort>
          <velocity>1.0</velocity>
        </limit>
        <dynamics>
          <damping>0.2088</damping>  <!-- # from [1] -->
          <friction>0.1413</friction>
          <!-- <damping>21.75</damping>  # from [2]
          <friction>3.48</friction> -->
          <spring_reference>0</spring_reference>
          <spring_stiffness>0</spring_stiffness>
        </dynamics>
      </axis>
    </joint>

    <link name="fr3_link2">
      <pose relative_to="fr3_joint2">0 0 0 0 0 0</pose>
      <inertial>
        <pose>-1.3177e-05 -0.070322 0.031178 0 0 0</pose>
        <mass>0.64693</mass>
        <inertia>
          <ixx>0.0038791</ixx>
          <ixy>-4.3728e-07</ixy>
          <ixz>-1.5169e-07</ixz>
          <iyy>0.0015493</iyy>
          <iyz>-0.00075277</iyz>
          <izz>0.0033662</izz>
        </inertia>
      </inertial>
      <visual name="fr3_link2_visual">
        <geometry>
          <mesh>
            <scale>1 1 1</scale>
            <uri>visual/link2.obj</uri>
          </mesh>
        </geometry>
      </visual>
      <collision name="fr3_link2_collision">
        <geometry>
          <mesh>
            <uri>collision/link2.obj</uri>
          </mesh>
        </geometry>
      </collision>
    </link>
    
    <joint name="fr3_joint3" type="revolute">
      <child>fr3_link3</child>
      <parent>fr3_link2</parent>
      <pose relative_to="fr3_link2">0 -0.316 0 1.57079632679 0 0</pose>
      <axis>
        <xyz>0 0 1</xyz>
        <limit>
          <lower>-2.4937</lower>
          <upper>2.4937</upper>
          <effort>87.0</effort>
          <velocity>1.50</velocity>
        </limit>
        <dynamics>
          <damping>0.0361</damping>  <!-- # from [1] -->
          <friction>0.1879</friction>
          <!-- <damping>21.75</damping>  # from [2]
          <friction>3.48</friction> -->
          <spring_reference>0</spring_reference>
          <spring_stiffness>0</spring_stiffness>
        </dynamics>
      </axis>
    </joint>

    <link name="fr3_link3">
      <pose relative_to="fr3_joint3">0 0 0 0 0 0</pose>
      <inertial>
        <pose>0.044348 0.024928 -0.03813 0 0 0</pose>
        <mass>3.2286</mass>
        <inertia>
          <ixx>0.010271</ixx>
          <ixy>-0.0019999</ixy>
          <ixz>-0.0034172</ixz>
          <iyy>0.012391</iyy>
          <iyz>-0.0018463</iyz>
          <izz>0.010383</izz>
        </inertia>
      </inertial>
      <visual name="fr3_link3_visual">
        <geometry>
          <mesh>
            <scale>1 1 1</scale>
            <uri>visual/link3.obj</uri>
          </mesh>
        </geometry>
      </visual>
      <collision name="fr3_link3_collision">
        <geometry>
          <mesh>
            <uri>collision/link3.obj</uri>
          </mesh>
        </geometry>
      </collision>
    </link>
    
    <joint name="fr3_joint4" type="revolute">
      <child>fr3_link4</child>
      <parent>fr3_link3</parent>
      <pose relative_to="fr3_link3">0.0825 0 0 1.57079632679 0 0</pose>
      <axis>
        <xyz>0 0 1</xyz>
        <limit>
          <lower>-2.7478</lower>
          <upper>-0.4461</upper>
          <effort>87.0</effort>
          <velocity>1.25</velocity>
        </limit>
        <dynamics>
          <damping>0.2174</damping>  <!-- # from [1] -->
          <friction>0.3625</friction>
          <!-- <damping>21.75</damping>  # from [2]
          <friction>3.48</friction> -->
          <spring_reference>0</spring_reference>
          <spring_stiffness>0</spring_stiffness>
        </dynamics>
      </axis>
    </joint>

    <link name="fr3_link4">
      <pose relative_to="fr3_joint4">0 0 0 0 0 0</pose>
      <inertial>
        <pose>-0.03855 0.039526 0.024716 0 0 0</pose>
        <mass>3.5879</mass>
        <inertia>
          <ixx>0.011671</ixx>
          <ixy>0.0038707</ixy>
          <ixz>-0.0022215</ixz>
          <iyy>0.011552</iyy>
          <iyz>0.0020927</iyz>
          <izz>0.014033</izz>
        </inertia>
      </inertial>
      <visual name="fr3_link4_visual">
        <geometry>
          <mesh>
            <scale>1 1 1</scale>
            <uri>visual/link4.obj</uri>
          </mesh>
        </geometry>
      </visual>
      <collision name="fr3_link4_collision">
        <geometry>
          <mesh>
            <uri>collision/link4.obj</uri>
          </mesh>
        </geometry>
      </collision>
    </link>
    
    <joint name="fr3_joint5" type="revolute">
      <child>fr3_link5</child>
      <parent>fr3_link4</parent>
      <pose relative_to="fr3_link4">-0.0825 0.384 0 -1.57079632679 0 0</pose>
      <axis>
        <xyz>0 0 1</xyz>
        <limit>
          <lower>-2.4800</lower>
          <upper>2.4800</upper>
          <effort>12.0</effort>
          <velocity>3.0</velocity>
        </limit>
        <dynamics>
          <damping>0.1021</damping>  <!-- # from [1] -->
          <friction>0.2728</friction>
          <!-- <damping>21.75</damping>  # from [2]
          <friction>3.48</friction> -->
          <spring_reference>0</spring_reference>
          <spring_stiffness>0</spring_stiffness>
        </dynamics>
      </axis>
    </joint>

    <link name="fr3_link5">
      <pose relative_to="fr3_joint5">0 0 0 0 0 0</pose>
      <inertial>
        <pose>-6.3678e-05 0.038412 -0.10997 0 0 0</pose>
        <mass>1.2259</mass>
        <inertia>
          <ixx>0.010699</ixx>
          <ixy>-3.3263e-06</ixy>
          <ixz>-1.4276e-05</ixz>
          <iyy>0.0097269</iyy>
          <iyz>-0.0021033</iyz>
          <izz>0.0027718</izz>
        </inertia>
      </inertial>
      <visual name="fr3_link5_visual">
        <geometry>
          <mesh>
            <scale>1 1 1</scale>
            <uri>visual/link5.obj</uri>
          </mesh>
        </geometry>
      </visual>
      <collision name="fr3_link5_collision">
        <geometry>
          <mesh>
            <uri>collision/link5.obj</uri>
          </mesh>
        </geometry>
      </collision>
    </link>
    
    <joint name="fr3_joint6" type="revolute">
      <child>fr3_link6</child>
      <parent>fr3_link5</parent>
      <pose relative_to="fr3_link5">0 0 0 1.57079632679 0 0</pose>
      <axis>
        <xyz>0 0 1</xyz>
        <limit>
          <lower>0.8521</lower>
          <upper>4.2094</upper>
          <effort>12.0</effort>
          <velocity>1.50</velocity>
        </limit>
        <dynamics>
          <damping>1.6128e-4</damping>  <!-- # from [1] -->
          <friction>0.1529</friction>
          <!-- <damping>21.75</damping>  # from [2]
          <friction>3.48</friction> -->
          <spring_reference>0</spring_reference>
          <spring_stiffness>0</spring_stiffness>
        </dynamics>
      </axis>
    </joint>

    <link name="fr3_link6">
      <pose relative_to="fr3_joint6">0 0 0 0 0 0</pose>
      <inertial>
        <pose>0.051002 0.0069327 0.006169 0 0 0</pose>
        <mass>1.6666</mass>
        <inertia>
          <ixx>0.0026926</ixx>
          <ixy>-0.00018935</ixy>
          <ixz>0.00034181</ixz>
          <iyy>0.004112</iyy>
          <iyz>3.3855e-05</iyz>
          <izz>0.0050102</izz>
        </inertia>
      </inertial>
      <visual name="fr3_link6_visual">
        <geometry>
          <mesh>
            <scale>1 1 1</scale>
            <uri>visual/link6.obj</uri>
          </mesh>
        </geometry>
      </visual>
      <collision name="fr3_link6_collision">
        <geometry>
          <mesh>
            <uri>collision/link6.obj</uri>
          </mesh>
        </geometry>
      </collision>
    </link>
    
    <joint name="fr3_joint7" type="revolute">
      <child>fr3_link7</child>
      <parent>fr3_link6</parent>
      <pose relative_to="fr3_link6">0.088 0 0 1.57079632679 0 0</pose>
      <axis>
        <xyz>0 0 1</xyz>
        <limit>
          <lower>-2.6895</lower>
          <upper>2.6895</upper>
          <effort>12.0</effort>
          <velocity>3.0</velocity>
        </limit>
        <dynamics>
          <damping>0.0632</damping>  <!-- # from [1] -->
          <friction>0.2097</friction>
          <!-- <damping>21.75</damping>  # from [2]
          <friction>3.48</friction> -->
          <spring_reference>0</spring_reference>
          <spring_stiffness>0</spring_stiffness>
        </dynamics>
      </axis>
    </joint>

    <link name="fr3_link7">
      <pose relative_to="fr3_joint7">0 0 0 0 0 0</pose>
      <inertial>
        <pose>0.010361 0.01036 0.079108 0 0 0</pose>
        <mass>0.73552</mass>
        <inertia>
          <ixx>0.00071284</ixx>
          <ixy>-0.00021805</ixy>
          <ixz>-2.3858e-05</ixz>
          <iyy>0.00071233</iyy>
          <iyz>-2.3938e-05</iyz>
          <izz>0.001122</izz>
        </inertia>
      </inertial>
      <visual name="fr3_link7_visual">
        <geometry>
          <mesh>
            <scale>1 1 1</scale>
            <uri>visual/link7.obj</uri>
          </mesh>
        </geometry>
      </visual>
      <collision name="fr3_link7_collision">
        <geometry>
          <mesh>
            <uri>collision/link7.obj</uri>
          </mesh>
        </geometry>
      </collision>
    </link>
    
    <joint name="fr3_hand_joint" type="fixed">
      <child>fr3_hand_link</child>
      <parent>fr3_link7</parent>
      <pose relative_to="fr3_link7">0 0 0.1034 0 0 0</pose>
    </joint>

    <link name="fr3_hand_link">
      <pose relative_to="fr3_hand_joint">0 0 0 0 0 -0.7853981633974484</pose>
      <inertial>
        <pose>-2.7666e-06 -0.00061547 0.02393 0 0 0</pose>
        <mass>0.73</mass>
        <inertia>
          <ixx>0.0024773</ixx>
          <ixy>-4.3259e-07</ixy>
          <ixz>9.8066e-08</ixz>
          <iyy>0.000498</iyy>
          <iyz>-4.4935e-05</iyz>
          <izz>0.0022417</izz>
        </inertia>
      </inertial>
      <visual name="fr3_hand_link_visual">
        <geometry>
          <mesh>
            <scale>1 1 1</scale>
            <uri>visual/hand.obj</uri>
          </mesh>
        </geometry>
      </visual>
      <collision name="fr3_hand_link_collision">
        <geometry>
          <mesh>
            <uri>collision/hand.obj</uri>
          </mesh>
        </geometry>
      </collision>
    </link>

    <joint name='fr3_left_finger_joint' type='prismatic'>
      <pose relative_to='fr3_hand_link'>0 0 0.0584 0 0 0</pose>
      <parent>fr3_hand_link</parent>
      <child>fr3_left_finger</child>
      <axis>
        <xyz>0 1 0</xyz>
        <limit>
          <lower>0</lower>
          <upper>0.04</upper>
          <effort>20</effort>
          <velocity>0.2</velocity>
        </limit>
        <dynamics>
          <damping>3.0</damping>
          <friction>0.4</friction>
          <spring_reference>0</spring_reference>
          <spring_stiffness>0</spring_stiffness>
        </dynamics>
      </axis>
    </joint>

    <link name="fr3_left_finger">
      <pose relative_to="fr3_left_finger_joint">0 0 0 0 0 0</pose>
        <inertial>
          <pose>-1.4235e-17 0.013887 0.02436 0 0 0</pose>
        <mass>0.015</mass>
          <inertia>
          <ixx>4.9423e-06</ixx>
          <ixy>-5.6195e-23</ixy>
          <ixz>-3.3497e-22</ixz>
          <iyy>4.7655e-06</iyy>
          <iyz>9.9792e-07</iyz>
          <izz>1.1104e-06</izz>
        </inertia>
        </inertial>
        <visual name="fr3_left_finger_visual">
          <geometry>
            <mesh>
              <scale>1 1 1</scale>
              <uri>visual/finger.obj</uri>
            </mesh>
          </geometry>
        </visual>
        <collision name="fr3_left_finger_collision">
          <geometry>
            <mesh>
              <uri>collision/finger.obj</uri>
            </mesh>
          </geometry>
        </collision>
    </link>

    <joint name='fr3_right_finger_joint' type='prismatic'>
      <pose relative_to='fr3_hand_link'>0 0 0.0584 0 0 0</pose>
      <parent>fr3_hand_link</parent>
      <child>fr3_right_finger</child>
      <axis>
        <xyz>0 -1 0</xyz>
        <limit>
          <lower>0</lower>
          <upper>0.04</upper>
          <effort>20</effort>
          <velocity>0.2</velocity>
        </limit>
        <dynamics>
          <damping>3.0</damping>
          <friction>0.4</friction>
          <spring_reference>0</spring_reference>
          <spring_stiffness>0</spring_stiffness>
        </dynamics>
      </axis>
    </joint>

    <link name="fr3_right_finger">
      <pose relative_to="fr3_right_finger_joint">0 0 0 0 0 0</pose>
        <inertial>
          <pose>-1.4235e-17 0.013887 0.02436 0 0 0</pose>
        <mass>0.015</mass>
          <inertia>
          <ixx>4.9423e-06</ixx>
          <ixy>-5.6195e-23</ixy>
          <ixz>-3.3497e-22</ixz>
          <iyy>4.7655e-06</iyy>
          <iyz>9.9792e-07</iyz>
          <izz>1.1104e-06</izz>
        </inertia>
        </inertial>
        <visual name="fr3_right_finger_visual">
          <pose>0 0 0 0 0 3.141592653589793</pose>
          <geometry>
            <mesh>
              <scale>1 1 1</scale>
              <uri>visual/finger.obj</uri>
            </mesh>
          </geometry>
        </visual>
        <collision name="fr3_right_finger_collision">
          <geometry>
            <mesh>
              <uri>collision/finger.obj</uri>
            </mesh>
          </geometry>
        </collision>
    </link>

  </model>
</sdf>
