<?xml version="1.0"?>
<!--
FR3 arm and hand together. See individual SDF files for comments.

Transformation between arm and hand taken from here: https://github.com/frankaemika/franka_ros/blob/develop/franka_description/robots/common/franka_hand.xacro
In particular, the location of the weld from the last link to the hand is given by the
"tcp" frame, and then there's an additional rotation of the hand by -pi/4 radians about
the local z axis.

[NOTE] Joint limits are NOT enforced when the plant runs in continuous time!
-->
<sdf version="1.7">
  <model name="fr3">
    <link name="fr3_link0">
      <inertial>
        <pose>-0.041018 -0.00014 0.049974 0 0 0</pose>
        <mass>0.629769</mass>
        <inertia>
          <ixx>0.00315</ixx>
          <ixy>8.2904e-07</ixy>
          <ixz>0.00015</ixz>
          <iyy>0.00388</iyy>
          <iyz>8.2299e-06</iyz>
          <izz>0.004285</izz>
        </inertia>
      </inertial>
      <visual name="fr3_link0_visual">
        <geometry>
          <mesh>
            <scale>1 1 1</scale>
            <uri>package://frogger/models/fr3/visual/link0.obj</uri>
          </mesh>
        </geometry>
      </visual>
      <collision name="fr3_link0_collision">
        <geometry>
          <mesh>
            <uri>package://frogger/models/fr3/collision/link0.obj</uri>
          </mesh>
        </geometry>
      </collision>
    </link>

    <joint name="fr3_joint1" type="revolute">
      <child>fr3_link1</child>
      <parent>fr3_link0</parent>
      <pose relative_to="fr3_link0">0 0 0.333 0 0 0</pose>
      <axis>
        <xyz>0 0 1</xyz>
        <limit>
          <lower>-2.3093</lower>
          <upper>2.3093 </upper>
          <effort>87.0</effort>
          <velocity>2.0</velocity>
        </limit>
        <dynamics>
          <damping>0.0628</damping>  <!-- # from [1] -->
          <friction>0.2549</friction>
          <!-- <damping>21.75</damping>  # from [2]
          <friction>3.48</friction> -->
          <spring_reference>0</spring_reference>
          <spring_stiffness>0</spring_stiffness>
        </dynamics>
      </axis>
    </joint>

    <link name="fr3_link1">
      <pose relative_to="fr3_joint1">0 0 0 0 0 0</pose>
      <inertial>
        <pose>0.003875 0.002081 -0.04762 0 0 0</pose>
        <mass>4.970684</mass>
        <inertia>
          <ixx>0.70337</ixx>
          <ixy>-0.00013900</ixy>
          <ixz>0.0067720</ixz>
          <iyy>0.70661</iyy>
          <iyz>0.019169</iyz>
          <izz>0.009117</izz>
        </inertia>
      </inertial>
      <visual name="fr3_link1_visual">
        <geometry>
          <mesh>
            <scale>1 1 1</scale>
            <uri>package://frogger/models/fr3/visual/link1.obj</uri>
          </mesh>
        </geometry>
      </visual>
      <collision name="fr3_link1_collision">
        <geometry>
          <mesh>
            <uri>package://frogger/models/fr3/collision/link1.obj</uri>
          </mesh>
        </geometry>
      </collision>
    </link>
    
    <joint name="fr3_joint2" type="revolute">
      <child>fr3_link2</child>
      <parent>fr3_link1</parent>
      <pose relative_to="fr3_link1">0 0 0 -1.57079632679 0 0</pose>
      <axis>
        <xyz>0 0 1</xyz>
        <limit>
          <lower>-1.5133</lower>
          <upper>1.5133</upper>
          <effort>87.0</effort>
          <velocity>1.0</velocity>
        </limit>
        <dynamics>
          <damping>0.2088</damping>  <!-- # from [1] -->
          <friction>0.1413</friction>
          <!-- <damping>21.75</damping>  # from [2]
          <friction>3.48</friction> -->
          <spring_reference>0</spring_reference>
          <spring_stiffness>0</spring_stiffness>
        </dynamics>
      </axis>
    </joint>

    <link name="fr3_link2">
      <pose relative_to="fr3_joint2">0 0 0 0 0 0</pose>
      <inertial>
        <pose>-0.003141 -0.02872  0.003495 0 0 0</pose>
        <mass>0.646926</mass>
        <inertia>
          <ixx>0.0079620</ixx>
          <ixy>-3.9250e-3</ixy>
          <ixz>1.0254e-02</ixz>
          <iyy>2.8110e-02</iyy>
          <iyz>7.0400e-04</iyz>
          <izz>2.5995e-02</izz>
        </inertia>
      </inertial>
      <visual name="fr3_link2_visual">
        <geometry>
          <mesh>
            <scale>1 1 1</scale>
            <uri>package://frogger/models/fr3/visual/link2.obj</uri>
          </mesh>
        </geometry>
      </visual>
      <collision name="fr3_link2_collision">
        <geometry>
          <mesh>
            <uri>package://frogger/models/fr3/collision/link2.obj</uri>
          </mesh>
        </geometry>
      </collision>
    </link>
    
    <joint name="fr3_joint3" type="revolute">
      <child>fr3_link3</child>
      <parent>fr3_link2</parent>
      <pose relative_to="fr3_link2">0 -0.316 0 1.57079632679 0 0</pose>
      <axis>
        <xyz>0 0 1</xyz>
        <limit>
          <lower>-2.4937</lower>
          <upper>2.4937</upper>
          <effort>87.0</effort>
          <velocity>1.50</velocity>
        </limit>
        <dynamics>
          <damping>0.0361</damping>  <!-- # from [1] -->
          <friction>0.1879</friction>
          <!-- <damping>21.75</damping>  # from [2]
          <friction>3.48</friction> -->
          <spring_reference>0</spring_reference>
          <spring_stiffness>0</spring_stiffness>
        </dynamics>
      </axis>
    </joint>

    <link name="fr3_link3">
      <pose relative_to="fr3_joint3">0 0 0 0 0 0</pose>
      <inertial>
        <pose>2.7518e-02 3.9252e-02 -6.6502e-02 0 0 0</pose>
        <mass>3.228604</mass>
        <inertia>
          <ixx>3.7242e-02</ixx>
          <ixy>-4.7610e-03</ixy>
          <ixz>-1.1396e-02</ixz>
          <iyy>3.6155e-02</iyy>
          <iyz>-1.2805e-02</iyz>
          <izz>1.0830e-02</izz>
        </inertia>
      </inertial>
      <visual name="fr3_link3_visual">
        <geometry>
          <mesh>
            <scale>1 1 1</scale>
            <uri>package://frogger/models/fr3/visual/link3.obj</uri>
          </mesh>
        </geometry>
      </visual>
      <collision name="fr3_link3_collision">
        <geometry>
          <mesh>
            <uri>package://frogger/models/fr3/collision/link3.obj</uri>
          </mesh>
        </geometry>
      </collision>
    </link>
    
    <joint name="fr3_joint4" type="revolute">
      <child>fr3_link4</child>
      <parent>fr3_link3</parent>
      <pose relative_to="fr3_link3">0.0825 0 0 1.57079632679 0 0</pose>
      <axis>
        <xyz>0 0 1</xyz>
        <limit>
          <lower>-2.7478</lower>
          <upper>-0.4461</upper>
          <effort>87.0</effort>
          <velocity>1.25</velocity>
        </limit>
        <dynamics>
          <damping>0.2174</damping>  <!-- # from [1] -->
          <friction>0.3625</friction>
          <!-- <damping>21.75</damping>  # from [2]
          <friction>3.48</friction> -->
          <spring_reference>0</spring_reference>
          <spring_stiffness>0</spring_stiffness>
        </dynamics>
      </axis>
    </joint>

    <link name="fr3_link4">
      <pose relative_to="fr3_joint4">0 0 0 0 0 0</pose>
      <inertial>
        <pose>-5.317e-02 1.04419e-01 2.7454e-02 0 0 0</pose>
        <mass>3.587895</mass>
        <inertia>
          <ixx>2.5853e-02</ixx>
          <ixy>7.7960e-03</ixy>
          <ixz>-1.3320e-03</ixz>
          <iyy>1.9552e-02</iyy>
          <iyz>8.6410e-03</iyz>
          <izz>2.8323e-02</izz>
        </inertia>
      </inertial>
      <visual name="fr3_link4_visual">
        <geometry>
          <mesh>
            <scale>1 1 1</scale>
            <uri>package://frogger/models/fr3/visual/link4.obj</uri>
          </mesh>
        </geometry>
      </visual>
      <collision name="fr3_link4_collision">
        <geometry>
          <mesh>
            <uri>package://frogger/models/fr3/collision/link4.obj</uri>
          </mesh>
        </geometry>
      </collision>
    </link>
    
    <joint name="fr3_joint5" type="revolute">
      <child>fr3_link5</child>
      <parent>fr3_link4</parent>
      <pose relative_to="fr3_link4">-0.0825 0.384 0 -1.57079632679 0 0</pose>
      <axis>
        <xyz>0 0 1</xyz>
        <limit>
          <lower>-2.4800</lower>
          <upper>2.4800</upper>
          <effort>12.0</effort>
          <velocity>3.0</velocity>
        </limit>
        <dynamics>
          <damping>0.1021</damping>  <!-- # from [1] -->
          <friction>0.2728</friction>
          <!-- <damping>21.75</damping>  # from [2]
          <friction>3.48</friction> -->
          <spring_reference>0</spring_reference>
          <spring_stiffness>0</spring_stiffness>
        </dynamics>
      </axis>
    </joint>

    <link name="fr3_link5">
      <pose relative_to="fr3_joint5">0 0 0 0 0 0</pose>
      <inertial>
        <pose>-1.1953e-02 4.1065e-02 -3.8437e-02 0 0 0</pose>
        <mass>1.225946</mass>
        <inertia>
          <ixx>3.5549e-02</ixx>
          <ixy>-2.1170e-03</ixy>
          <ixz>-4.0370e-03</ixz>
          <iyy>2.9474e-02</iyy>
          <iyz>2.2900e-04</iyz>
          <izz>8.6270e-03</izz>
        </inertia>
      </inertial>
      <visual name="fr3_link5_visual">
        <geometry>
          <mesh>
            <scale>1 1 1</scale>
            <uri>package://frogger/models/fr3/visual/link5.obj</uri>
          </mesh>
        </geometry>
      </visual>
      <collision name="fr3_link5_collision">
        <geometry>
          <mesh>
            <uri>package://frogger/models/fr3/collision/link5.obj</uri>
          </mesh>
        </geometry>
      </collision>
    </link>
    
    <joint name="fr3_joint6" type="revolute">
      <child>fr3_link6</child>
      <parent>fr3_link5</parent>
      <pose relative_to="fr3_link5">0 0 0 1.57079632679 0 0</pose>
      <axis>
        <xyz>0 0 1</xyz>
        <limit>
          <lower>0.8521</lower>
          <upper>4.2094</upper>
          <effort>12.0</effort>
          <velocity>1.50</velocity>
        </limit>
        <dynamics>
          <damping>1.6128e-4</damping>  <!-- # from [1] -->
          <friction>0.1529</friction>
          <!-- <damping>21.75</damping>  # from [2]
          <friction>3.48</friction> -->
          <spring_reference>0</spring_reference>
          <spring_stiffness>0</spring_stiffness>
        </dynamics>
      </axis>
    </joint>

    <link name="fr3_link6">
      <pose relative_to="fr3_joint6">0 0 0 0 0 0</pose>
      <inertial>
        <pose>6.0149e-02 -1.4117e-02 -1.0517e-02 0 0 0</pose>
        <mass>1.666555</mass>
        <inertia>
          <ixx>1.9640e-03</ixx>
          <ixy>1.0900e-04</ixy>
          <ixz>-1.1580e-03</ixz>
          <iyy>4.3540e-03</iyy>
          <iyz>3.4100e-04</iyz>
          <izz>5.4330e-03</izz>
        </inertia>
      </inertial>
      <visual name="fr3_link6_visual">
        <geometry>
          <mesh>
            <scale>1 1 1</scale>
            <uri>package://frogger/models/fr3/visual/link6.obj</uri>
          </mesh>
        </geometry>
      </visual>
      <collision name="fr3_link6_collision">
        <geometry>
          <mesh>
            <uri>package://frogger/models/fr3/collision/link6.obj</uri>
          </mesh>
        </geometry>
      </collision>
    </link>
    
    <joint name="fr3_joint7" type="revolute">
      <child>fr3_link7</child>
      <parent>fr3_link6</parent>
      <pose relative_to="fr3_link6">0.088 0 0 1.57079632679 0 0</pose>
      <axis>
        <xyz>0 0 1</xyz>
        <limit>
          <lower>-2.6895</lower>
          <upper>2.6895</upper>
          <effort>12.0</effort>
          <velocity>3.0</velocity>
        </limit>
        <dynamics>
          <damping>0.0632</damping>  <!-- # from [1] -->
          <friction>0.2097</friction>
          <!-- <damping>21.75</damping>  # from [2]
          <friction>3.48</friction> -->
          <spring_reference>0</spring_reference>
          <spring_stiffness>0</spring_stiffness>
        </dynamics>
      </axis>
    </joint>

    <link name="fr3_link7">
      <pose relative_to="fr3_joint7">0 0 0 0 0 0</pose>
      <inertial>
        <pose>1.0517e-02 -4.252e-03 6.1597e-02 0 0 0</pose>
        <mass>7.35522e-01</mass>
        <inertia>
          <ixx>1.2516e-02</ixx>
          <ixy>-4.2800e-04</ixy>
          <ixz>-1.1960e-03</ixz>
          <iyy>1.0027e-02</iyy>
          <iyz>-7.4100e-04</iyz>
          <izz>4.8150e-03</izz>
        </inertia>
      </inertial>
      <visual name="fr3_link7_visual">
        <geometry>
          <mesh>
            <scale>1 1 1</scale>
            <uri>package://frogger/models/fr3/visual/link7.dae</uri>
          </mesh>
        </geometry>
      </visual>
      <collision name="fr3_link7_collision">
        <geometry>
          <mesh>
            <uri>package://frogger/models/fr3/collision/link7.obj</uri>
          </mesh>
        </geometry>
      </collision>
    </link>
    
    <joint name="fr3_hand_joint" type="fixed">
      <child>fr3_hand_link</child>
      <parent>fr3_link7</parent>
      <pose relative_to="fr3_link7">0 0 0.1034 0 0 0</pose>
    </joint>

    <link name="fr3_hand_link">
      <pose relative_to="fr3_hand_joint">0 0 0 0 0 -0.7853981633974484</pose>
      <inertial>
        <pose>-0.01 0 0.03 0 0 0</pose>
        <mass>0.73</mass>
        <inertia>
          <ixx>0.001</ixx>
          <ixy>0.0</ixy>
          <ixz>0.0</ixz>
          <iyy>0.0025</iyy>
          <iyz>0.0</iyz>
          <izz>0.0017</izz>
        </inertia>
      </inertial>
      <visual name="fr3_hand_link_visual">
        <geometry>
          <mesh>
            <scale>1 1 1</scale>
            <uri>package://frogger/models/fr3/visual/hand.obj</uri>
          </mesh>
        </geometry>
      </visual>
      <collision name="fr3_hand_link_collision">
        <geometry>
          <mesh>
            <uri>package://frogger/models/fr3/collision/hand.obj</uri>
          </mesh>
        </geometry>
      </collision>
    </link>

    <joint name='fr3_left_finger_joint' type='prismatic'>
      <pose relative_to='fr3_hand_link'>0 0 0.0584 0 0 0</pose>
      <parent>fr3_hand_link</parent>
      <child>fr3_left_finger</child>
      <axis>
        <xyz>0 1 0</xyz>
        <limit>
          <lower>0</lower>
          <upper>0.04</upper>
          <effort>20</effort>
          <velocity>0.2</velocity>
        </limit>
        <dynamics>
          <damping>3.0</damping>
          <friction>0.4</friction>
          <spring_reference>0</spring_reference>
          <spring_stiffness>0</spring_stiffness>
        </dynamics>
      </axis>
    </joint>

    <link name="fr3_left_finger">
      <pose relative_to="fr3_left_finger_joint">0 0 0 0 0 0</pose>
        <inertial>
          <mass>0.015</mass>
          <inertia>
            <ixx>2.3749999999999997e-06</ixx>
            <ixy>0.0</ixy>
            <ixz>0.0</ixz>
            <iyy>2.3749999999999997e-06</iyy>
            <iyz>0.0</iyz>
            <izz>7.5e-07</izz>
          </inertia>
        </inertial>
        <visual name="fr3_left_finger_visual">
          <geometry>
            <mesh>
              <scale>1 1 1</scale>
              <uri>package://frogger/models/fr3/visual/finger.obj</uri>
            </mesh>
          </geometry>
        </visual>
        <collision name="fr3_left_finger_collision">
          <geometry>
            <mesh>
              <uri>package://frogger/models/fr3/collision/finger.obj</uri>
            </mesh>
          </geometry>
        </collision>
    </link>

    <joint name='fr3_right_finger_joint' type='prismatic'>
      <pose relative_to='fr3_hand_link'>0 0 0.0584 0 0 0</pose>
      <parent>fr3_hand_link</parent>
      <child>fr3_right_finger</child>
      <axis>
        <xyz>0 -1 0</xyz>
        <limit>
          <lower>0</lower>
          <upper>0.04</upper>
          <effort>20</effort>
          <velocity>0.2</velocity>
        </limit>
        <dynamics>
          <damping>3.0</damping>
          <friction>0.4</friction>
          <spring_reference>0</spring_reference>
          <spring_stiffness>0</spring_stiffness>
        </dynamics>
      </axis>
    </joint>

    <link name="fr3_right_finger">
      <pose relative_to="fr3_right_finger_joint">0 0 0 0 0 0</pose>
        <inertial>
          <mass>0.015</mass>
          <inertia>
            <ixx>2.3749999999999997e-06</ixx>
            <ixy>0.0</ixy>
            <ixz>0.0</ixz>
            <iyy>2.3749999999999997e-06</iyy>
            <iyz>0.0</iyz>
            <izz>7.5e-07</izz>
          </inertia>
        </inertial>
        <visual name="fr3_right_finger_visual">
          <pose>0 0 0 0 0 3.141592653589793</pose>
          <geometry>
            <mesh>
              <scale>1 1 1</scale>
              <uri>package://frogger/models/fr3/visual/finger.obj</uri>
            </mesh>
          </geometry>
        </visual>
        <collision name="fr3_right_finger_collision">
          <geometry>
            <mesh>
              <uri>package://frogger/models/fr3/collision/finger.obj</uri>
            </mesh>
          </geometry>
        </collision>
    </link>

  </model>
</sdf>