<?xml version="1.0"?>
<!--
Values in this SDF are Panda values taken from a Franka SysID paper on the Panda: https://github.com/frankaemika/franka_ros/blob/develop/franka_description/robots/common/inertial.yaml

Joint limits are from: https://github.com/frankaemika/franka_ros/blob/develop/franka_description/robots/fr3/joint_limits.yaml

Joint friction parameters are from [1]: https://github.com/marcocognetti/FrankaEmikaPandaDynModel/blob/master/pdf/RA-L_2019_PandaDynIdent_SUPPLEMENTARY_MATERIAL.pdf
[NOTE] they use a friction model with viscous and coulomb friction but ALSO with a
"coulomb friction offset" term, which isn't represented here but has fairly significant
effect on the friction value. I report the values from Table III in the OSI column. 

Another repo that helped me debug [2]: https://github.com/AndrejOrsula/panda_ign_moveit2/blob/master/panda_description/panda/model.sdf

The visual geometries are OBJ/MTL file pairs converted from the original DAE files
provided by Franka.

The collision geometries are custom chosen by visual inspection.

[NOTE] Joint limits are NOT enforced when the plant runs in continuous time!
-->
<sdf version="1.7">
  <model name="fr3_arm">
    <link name="fr3_link0">
      <inertial>
        <pose>-0.03762 0 0.061412 0 0 0</pose>
        <mass>0.62977</mass>
        <inertia>
          <ixx>0.0019855</ixx>
          <ixy>0</ixy>
          <ixz>-0.0001985</ixz>
          <iyy>0.0034589</iyy>
          <iyz>0</iyz>
          <izz>0.0036964</izz>
        </inertia>
      </inertial>
      <visual name="fr3_link0_visual">
        <geometry>
          <mesh>
            <scale>1 1 1</scale>
            <uri>visual/link0.obj</uri>
          </mesh>
        </geometry>
      </visual>
      <collision name="fr3_link0_collision_1">
        <pose>-0.043 0.0 0.05 0.0 0.0 0.0</pose>
        <geometry>
          <box>
            <size>0.23 0.15 0.1</size>
          </box>
        </geometry>
      </collision>
      <collision name="fr3_link0_collision_2">
        <pose>-0.01 0.0 0.12 0.0 0.0 0.0</pose>
        <geometry>
          <box>
            <size>0.14 0.12 0.04</size>
          </box>
        </geometry>
      </collision>
    </link>

    <joint name="fr3_joint1" type="revolute">
      <child>fr3_link1</child>
      <parent>fr3_link0</parent>
      <pose relative_to="fr3_link0">0 0 0.333 0 0 0</pose>
      <axis>
        <xyz>0 0 1</xyz>
        <limit>
          <lower>-2.3093</lower>
          <upper>2.3093 </upper>
          <effort>87.0</effort>
          <velocity>2.0</velocity>
        </limit>
        <dynamics>
          <damping>0.0628</damping>  <!-- # from [1] -->
          <friction>0.2549</friction>
          <!-- <damping>21.75</damping>  # from [2]
          <friction>3.48</friction> -->
          <spring_reference>0</spring_reference>
          <spring_stiffness>0</spring_stiffness>
        </dynamics>
      </axis>
    </joint>

    <link name="fr3_link1">
      <pose relative_to="fr3_joint1">0 0 0 0 0 0</pose>
      <inertial>
        <pose>0 -0.016667 -0.05 0 0 0</pose>
        <mass>4.9707</mass>
        <inertia>
          <ixx>0.040696</ixx>
          <ixy>0</ixy>
          <ixz>0</ixz>
          <iyy>0.027895</iyy>
          <iyz>0.0014881</iyz>
          <izz>0.021218</izz>
        </inertia>
      </inertial>
      <visual name="fr3_link1_visual">
        <geometry>
          <mesh>
            <scale>1 1 1</scale>
            <uri>visual/link1.obj</uri>
          </mesh>
        </geometry>
      </visual>
      <collision name="fr3_link1_collision_1">
        <pose>0.0 -0.05 -0.05 0.52359877559 0.0 0.0</pose>
        <geometry>
          <capsule>
            <length>0.1</length>
            <radius>0.06</radius>
          </capsule>
        </geometry>
      </collision>
      <collision name="fr3_link1_collision_2">
        <pose>0.0 0.0 -0.15 0.0 0.0 0.0</pose>
        <geometry>
          <cylinder>
            <length>0.12</length>
            <radius>0.06</radius>
          </cylinder>
        </geometry>
      </collision>
      <collision name="fr3_link1_collision_3">
        <pose>0.0 0.0 0.0 1.57079632679 0.0 0.0</pose>
        <geometry>
          <capsule>
            <length>0.16</length>
            <radius>0.06</radius>
          </capsule>
        </geometry>
      </collision>
    </link>
    
    <joint name="fr3_joint2" type="revolute">
      <child>fr3_link2</child>
      <parent>fr3_link1</parent>
      <pose relative_to="fr3_link1">0 0 0 -1.57079632679 0 0</pose>
      <axis>
        <xyz>0 0 1</xyz>
        <limit>
          <lower>-1.5133</lower>
          <upper>1.5133</upper>
          <effort>87.0</effort>
          <velocity>1.0</velocity>
        </limit>
        <dynamics>
          <damping>0.2088</damping>  <!-- # from [1] -->
          <friction>0.1413</friction>
          <!-- <damping>21.75</damping>  # from [2]
          <friction>3.48</friction> -->
          <spring_reference>0</spring_reference>
          <spring_stiffness>0</spring_stiffness>
        </dynamics>
      </axis>
    </joint>

    <link name="fr3_link2">
      <pose relative_to="fr3_joint2">0 0 0 0 0 0</pose>
      <inertial>
        <pose>0 -0.12064 0.025641 0 0 0</pose>
        <mass>0.64693</mass>
        <inertia>
          <ixx>0.0065165</ixx>
          <ixy>0</ixy>
          <ixz>0</ixz>
          <iyy>0.0016969</iyy>
          <iyz>-0.0015597</iyz>
          <izz>0.0058885</izz>
        </inertia>
      </inertial>
      <visual name="fr3_link2_visual">
        <geometry>
          <mesh>
            <scale>1 1 1</scale>
            <uri>visual/link2.obj</uri>
          </mesh>
        </geometry>
      </visual>
      <collision name="fr3_link2_collision_1">
        <pose>0.0 -0.195 0.0 1.57079632679 0.0 0.0</pose>
        <geometry>
          <capsule>
            <length>0.11</length>
            <radius>0.06</radius>
          </capsule>
        </geometry>
      </collision>
      <collision name="fr3_link2_collision_2">
        <pose>0.0 -0.05 0.05 -1.0471975512 0.0 0.0</pose>
        <geometry>
          <capsule>
            <length>0.12</length>
            <radius>0.06</radius>
          </capsule>
        </geometry>
      </collision>
    </link>
    
    <joint name="fr3_joint3" type="revolute">
      <child>fr3_link3</child>
      <parent>fr3_link2</parent>
      <pose relative_to="fr3_link2">0 -0.316 0 1.57079632679 0 0</pose>
      <axis>
        <xyz>0 0 1</xyz>
        <limit>
          <lower>-2.4937</lower>
          <upper>2.4937</upper>
          <effort>87.0</effort>
          <velocity>1.50</velocity>
        </limit>
        <dynamics>
          <damping>0.0361</damping>  <!-- # from [1] -->
          <friction>0.1879</friction>
          <!-- <damping>21.75</damping>  # from [2]
          <friction>3.48</friction> -->
          <spring_reference>0</spring_reference>
          <spring_stiffness>0</spring_stiffness>
        </dynamics>
      </axis>
    </joint>

    <link name="fr3_link3">
      <pose relative_to="fr3_joint3">0 0 0 0 0 0</pose>
      <inertial>
        <pose>0.072143 0.01 -0.0085714 0 0 0</pose>
        <mass>3.2286</mass>
        <inertia>
          <ixx>0.012774</ixx>
          <ixy>0.0010378</ixy>
          <ixz>-0.00088951</ixz>
          <iyy>0.0070746</iyy>
          <iyz>0.00069184</iyz>
          <izz>0.013515</izz>
        </inertia>
      </inertial>
      <visual name="fr3_link3_visual">
        <geometry>
          <mesh>
            <scale>1 1 1</scale>
            <uri>visual/link3.obj</uri>
          </mesh>
        </geometry>
      </visual>
      <collision name="fr3_link3_collision_1">
        <pose>0.04 0.035 -0.03 0.0 0.0 0.0</pose>
        <geometry>
          <sphere>
            <radius>0.06</radius>
          </sphere>
        </geometry>
      </collision>
      <collision name="fr3_link3_collision_2">
        <pose>0.085 0.0 0.0 1.57079632679 0.0 0.0</pose>
        <geometry>
          <capsule>
            <length>0.12</length>
            <radius>0.06</radius>
          </capsule>
        </geometry>
      </collision>
    </link>
    
    <joint name="fr3_joint4" type="revolute">
      <child>fr3_link4</child>
      <parent>fr3_link3</parent>
      <pose relative_to="fr3_link3">0.0825 0 0 1.57079632679 0 0</pose>
      <axis>
        <xyz>0 0 1</xyz>
        <limit>
          <lower>-2.7478</lower>
          <upper>-0.4461</upper>
          <effort>87.0</effort>
          <velocity>1.25</velocity>
        </limit>
        <dynamics>
          <damping>0.2174</damping>  <!-- # from [1] -->
          <friction>0.3625</friction>
          <!-- <damping>21.75</damping>  # from [2]
          <friction>3.48</friction> -->
          <spring_reference>0</spring_reference>
          <spring_stiffness>0</spring_stiffness>
        </dynamics>
      </axis>
    </joint>

    <link name="fr3_link4">
      <pose relative_to="fr3_joint4">0 0 0 0 0 0</pose>
      <inertial>
        <pose>-0.08 0.11 0 0 0 0</pose>
        <mass>3.5879</mass>
        <inertia>
          <ixx>0.013326</ixx>
          <ixy>0</ixy>
          <ixz>0</ixz>
          <iyy>0.0058841</iyy>
          <iyz>3.6439e-14</iyz>
          <izz>0.013326</izz>
        </inertia>
      </inertial>
      <visual name="fr3_link4_visual">
        <geometry>
          <mesh>
            <scale>1 1 1</scale>
            <uri>visual/link4.obj</uri>
          </mesh>
        </geometry>
      </visual>
      <collision name="fr3_link4_collision_1">
        <pose>-0.08 0.11 0.0 1.57079632679 0.0 0.0</pose>
        <geometry>
          <capsule>
            <length>0.1</length>
            <radius>0.06</radius>
          </capsule>
        </geometry>
      </collision>
      <!-- <collision name="fr3_link4_collision_2">
        <pose>-0.035 0.03 0.04 0.0 0.0 0.0</pose>
        <geometry>
          <sphere>
            <radius>0.05</radius>
          </sphere>
        </geometry>
      </collision> -->
    </link>
    
    <joint name="fr3_joint5" type="revolute">
      <child>fr3_link5</child>
      <parent>fr3_link4</parent>
      <pose relative_to="fr3_link4">-0.0825 0.384 0 -1.57079632679 0 0</pose>
      <axis>
        <xyz>0 0 1</xyz>
        <limit>
          <lower>-2.4800</lower>
          <upper>2.4800</upper>
          <effort>12.0</effort>
          <velocity>3.0</velocity>
        </limit>
        <dynamics>
          <damping>0.1021</damping>  <!-- # from [1] -->
          <friction>0.2728</friction>
          <!-- <damping>21.75</damping>  # from [2]
          <friction>3.48</friction> -->
          <spring_reference>0</spring_reference>
          <spring_stiffness>0</spring_stiffness>
        </dynamics>
      </axis>
    </joint>

    <link name="fr3_link5">
      <pose relative_to="fr3_joint5">0 0 0 0 0 0</pose>
      <inertial>
        <pose>0 0.054052 -0.031226 0 0 0</pose>
        <mass>1.2259</mass>
        <inertia>
          <ixx>0.0073008</ixx>
          <ixy>0</ixy>
          <ixz>0</ixz>
          <iyy>0.005003</iyy>
          <iyz>0.00097758</iyz>
          <izz>0.0035848</izz>
        </inertia>
      </inertial>
      <visual name="fr3_link5_visual">
        <geometry>
          <mesh>
            <scale>1 1 1</scale>
            <uri>visual/link5.obj</uri>
          </mesh>
        </geometry>
      </visual>
      <!-- <collision name="fr3_link5_collision_1">
        <pose>0.0 0.033 -0.19 0.0 0.0 0.0</pose>
        <geometry>
          <sphere>
            <radius>0.055</radius>
          </sphere>
        </geometry>
      </collision> -->
      <collision name="fr3_link5_collision_2">
        <pose>0.0 0.085 -0.1 -0.174533 0.0 0.0</pose>
        <geometry>
          <box>
            <size>0.07 0.045 0.2</size>
          </box>
        </geometry>
      </collision>
      <collision name="fr3_link5_collision_3">
        <pose>0.0 0.04 0.0 1.57079632679 0.0 0.0</pose>
        <geometry>
          <capsule>
            <length>0.11</length>
            <radius>0.05</radius>
          </capsule>
        </geometry>
      </collision>
    </link>
    
    <joint name="fr3_joint6" type="revolute">
      <child>fr3_link6</child>
      <parent>fr3_link5</parent>
      <pose relative_to="fr3_link5">0 0 0 1.57079632679 0 0</pose>
      <axis>
        <xyz>0 0 1</xyz>
        <limit>
          <lower>0.8521</lower>
          <upper>4.2094</upper>
          <effort>12.0</effort>
          <velocity>1.50</velocity>
        </limit>
        <dynamics>
          <damping>1.6128e-4</damping>  <!-- # from [1] -->
          <friction>0.1529</friction>
          <!-- <damping>21.75</damping>  # from [2]
          <friction>3.48</friction> -->
          <spring_reference>0</spring_reference>
          <spring_stiffness>0</spring_stiffness>
        </dynamics>
      </axis>
    </joint>

    <link name="fr3_link6">
      <pose relative_to="fr3_joint6">0 0 0 0 0 1.57079632679</pose>
      <!-- <pose relative_to="fr3_joint6">0 0 0 0 0 0</pose> -->  <!-- original -->
      <inertial>
        <pose>0.063231 -0.0021948 0.0078052 0 0 0</pose>
        <mass>1.6666</mass>
        <inertia>
          <ixx>0.00454</ixx>
          <ixy>0.00043226</ixy>
          <ixz>0.00043226</ixz>
          <iyy>0.0034907</iyy>
          <iyz>-0.00015863</iyz>
          <izz>0.0055593</izz>
        </inertia>
      </inertial>
      <visual name="fr3_link6_visual">
        <geometry>
          <mesh>
            <scale>1 1 1</scale>
            <uri>visual/link6.obj</uri>
          </mesh>
        </geometry>
      </visual>
      <collision name="fr3_link6_collision_1">
        <pose>0.03 0.01 0.02 0.0 0.0 0.0</pose>
        <geometry>
          <sphere>
            <radius>0.06</radius>
          </sphere>
        </geometry>
      </collision>
      <collision name="fr3_link6_collision_2">
        <pose>0.0845 -0.01 0.0 1.57079632679 0.0 0.0</pose>
        <geometry>
          <capsule>
            <length>0.105</length>
            <radius>0.051</radius>
          </capsule>
        </geometry>
      </collision>
    </link>
    
    <joint name="fr3_joint7" type="revolute">
      <child>fr3_link7</child>
      <parent>fr3_link6</parent>
      <pose relative_to="fr3_link6">0.088 0 0 1.57079632679 0 0</pose>
      <axis>
        <xyz>0 0 1</xyz>
        <limit>
          <lower>-2.6895</lower>
          <upper>2.6895</upper>
          <effort>12.0</effort>
          <velocity>3.0</velocity>
        </limit>
        <dynamics>
          <damping>0.0632</damping>  <!-- # from [1] -->
          <friction>0.2097</friction>
          <!-- <damping>21.75</damping>  # from [2]
          <friction>3.48</friction> -->
          <spring_reference>0</spring_reference>
          <spring_stiffness>0</spring_stiffness>
        </dynamics>
      </axis>
    </joint>

    <link name="fr3_link7">
      <pose relative_to="fr3_joint7">0 0 0 0 0 0</pose>
      <inertial>
        <pose>0.012874 0.01264 0.08083 0 0 0</pose>
        <mass>0.73552</mass>
        <inertia>
          <ixx>0.00066482</ixx>
          <ixy>-0.00020314</ixy>
          <ixz>-1.4906e-05</ixz>
          <iyy>0.00066981</iyy>
          <iyz>-1.5135e-05</iyz>
          <izz>0.0010836</izz>
        </inertia>
      </inertial>
      <visual name="fr3_link7_visual">
        <geometry>
          <mesh>
            <scale>1 1 1</scale>
            <uri>visual/link7.obj</uri>
          </mesh>
        </geometry>
      </visual>
      <collision name="fr3_link7_collision_1">
        <pose>0.0275 0.027 0.087 0.0 0.0 -0.78539816339</pose>
        <geometry>
          <box>
            <size>0.07 0.1 0.02</size>
          </box>
        </geometry>
      </collision>
      <collision name="fr3_link7_collision_2">
        <pose>0.0 0.0 0.082 0.0 0.0 -0.78539816339</pose>
        <geometry>
          <cylinder>
            <radius>0.045</radius>
            <length>0.05</length>
          </cylinder>
        </geometry>
      </collision>
      <collision name="fr3_link7_collision_3">
        <pose>0.0275 0.027 0.072 0.3 0.0 -0.78539816339</pose>
        <geometry>
          <box>
            <size>0.07 0.1 0.02</size>
          </box>
        </geometry>
      </collision>
    </link>
    
  </model>
</sdf>
